Workbook

Sheet 00_总览
A2: 汴梁游记 成员2数据工作簿 v1.1
A4: 本工作簿依据新的项目总体设计、数据需求和四人任务分工重建，服务于成员2的第一轮工作：建立统一表结构、字段字典、ID与格式规范，并为自动校验、异常清单、增量导入和质量报告提供可执行基础。
A7: 核心数据表 | B7: 12 | D7: 第一轮放行条件
A8: 字段定义 | B8: 228 | D8: 12张核心表、字段字典、媒体权限与状态取值已定版。
A9: 成员2首轮任务 | B9: 10 | D9: 成员1/3/4提交的数据能按统一ID导入，并被定位到原始来源。
A10: 校验规则 | B10: 21 | D10: 自动校验能发现重复、缺失、无效坐标、时间冲突和跨表断链。
A11: 状态码 | B11: 61 | D11: 所有异常都有记录ID、处理状态、负责人和变更日志。
D12: 报告分别统计候选数据与已核实数据，不合并成一个成功数量。
A14: 输入依据
A15: 项目总体设计 | B15: 全项目任务与交付路线图 | C15: 2026-10-20版本 | D15: 确认产品闭环、M0/M1边界和C/D/E数据任务
A16: 项目所需要的数据 | B16: 城市旅游智能体数据收集与实施清单 | C16: 14页 | D16: 确认10张核心表、字段、来源、时效与验收规则
A17: 任务分工 | B17: 四人数据采集任务书与质量验收标准 | C17: 7页 | D17: 确认成员2职责、第一轮目标、交付物与3天节奏
A19: 使用顺序：先由成员1/3/4按工作表中的候选/核验状态录数；成员2只做结构整合、关联检查、问题登记和版本管理。程序校验不能替代入口、场次、路网、商家供应的现场或官方核实。
A22: v1.1更新：新增22_media_assets与23_media_relations；修正“当前候选数”只统计candidate状态；将供应关系的verified_at改为条件必填；新增89_初筛报告。成员1和成员4原填写内容保留。

Sheet 01_成员2任务
A1: 成员2第一轮任务
A2: 按三天试采节奏拆分。状态由成员2维护，完成时必须在证据列填写可定位文件、命令或链接。
A4: 任务ID | B4: 第一轮动作 | C4: 产出物 | D4: 验收标准 | E4: 依赖与协作 | F4: 建议完成日 | G4: 状态 | H4: 证据链接/文件
A5: M2-R1-01 | B5: 冻结第一轮10张核心表与字段字典 | C5: 统一Excel模板、字段字典、状态取值表 | D5: 表名、字段名、类型和必填规则一致，可直接分工填写 | E5: 成员2；依赖成员1/3/4口径 | F5: 第1天 | G5: 进行中 | H5: 本工作簿
A6: M2-R1-02 | B6: 制定唯一ID和关联规则 | C6: ID规则说明、跨表外键关系 | D6: 景点、入口、规则、节目、场次、商家、菜品、来源均有稳定ID | E6: 成员2 | F6: 第1天 | G6: 进行中 | H6: 字段字典/使用说明
A7: M2-R1-03 | B7: 统一时间、坐标、单位与状态格式 | C7: 格式校验约束 | D7: 日期含日期与时区，坐标必须带CRS，距离米、耗时秒、价格人民币 | E7: 成员2；成员3核对CRS | F7: 第1天 | G7: 进行中 | H7: 99_使用说明
A8: M2-R1-04 | B8: 建立自动校验规则集 | C8: 90_校验规则、后续校验脚本 | D8: 覆盖重复ID、重复记录、必填缺失、无效坐标、时间逻辑和跨表断链 | E8: 成员2 | F8: 第2天 | G8: 待开始 | H8: 90_校验规则
A9: M2-R1-05 | B9: 建立异常清单处理状态 | C9: 问题表字段规范、处理状态 | D9: 每个异常可定位到记录ID、负责人和处理结论 | E9: 成员2 | F9: 第2天 | G9: 待开始 | H9: 91_状态与取值
A10: M2-R1-06 | B10: 完成第一批数据导入试跑 | C10: 导入记录、错误清单、修复前后对照 | D10: 同一批数据重复运行结果一致，不覆盖原始版本 | E10: 成员2；成员1/3/4提交数据 | F10: 第2天 | G10: 待开始 | H10: 导入后补证据
A11: M2-R1-07 | B11: 生成本轮数据质量报告 | C11: 候选数、已核实数、缺失率、重复数、冲突数、关联率 | D11: 候选与已核实分开统计，不以格式正确替代事实核实 | E11: 成员2 | F11: 第3天 | G11: 待开始 | H11: 质量报告
A12: M2-R1-08 | B12: 交付第一轮数据包并保留变更日志 | C12: 工作簿、原始证据索引、问题清单、版本记录 | D12: 原始数据未被覆盖或丢弃，可追溯到来源 | E12: 成员2；全组验收 | F12: 第3天 | G12: 待开始 | H12: 最终归档
A13: M2-R1-09 | B13: 冻结图片、视频等媒体资产结构 | C13: 媒体资产表、媒体关联表、权限和隐私字段 | D13: 成员1/4可登记图片视频，不再改动原有地点和商家字段 | E13: 成员2；需成员1/4确认媒体来源与权限 | F13: 第4天 | G13: 完成 | H13: 22/23工作表与字段字典
A14: M2-R1-10 | B14: 发布初筛报告与最新版模板 | C14: v1.1工作簿、初筛报告、问题清单 | D14: 839条现有记录保留，重复/格式/断链有结论，媒体结构已补齐 | E14: 成员2；全组复核 | F14: 第4天 | G14: 完成 | H14: v1.1工作簿与89_初筛报告

Sheet 02_字段字典
A1: 字段字典
A2: 第一轮字段口径。字段名用于程序与跨表关联，中文名称用于团队填写和审核。
A3: 序号 | B3: 工作表 | C3: 字段名 | D3: 中文名称 | E3: 数据类型 | F3: 必填 | G3: 格式示例 | H3: 允许值/约束 | I3: 说明
A4: 1 | B4: 10_places | C4: place_id | D4: 地点ID | E4: string | F4: Y | G4: pl_000001 | H4: 唯一稳定ID；不得用名称代替 | I4: 地点主键。
A5: 2 | B5: 10_places | C5: name | D5: 标准名称 | E5: string | F5: Y | G5: 地点标准名称 | I5: 游客可识别的正式名称。
A6: 3 | B6: 10_places | C6: place_type | D6: 地点类别 | E6: enum | F6: Y | G6: scenic_spot | H6: scenic_spot|night_market|food_street|transport_hub|stage|service_point | I6: 城市景点、夜市、餐饮街区、交通枢纽、舞台等。
A7: 4 | B7: 10_places | C7: parent_place_id | D7: 上级地点ID | E7: string | F7: N | G7: pl_000010 | I7: 景区归属或街区归属；用于层级关系。
A8: 5 | B8: 10_places | C8: address | D8: 地址 | E8: string | F8: N | G8: 详细地址 | I8: 公开地址或核实结果。
A9: 6 | B9: 10_places | C9: lng | D9: 经度 | E9: number | F9: N | G9: 114.3500000 | H9: [-180,180] | I9: WGS84/GCJ-02等须与crs一致。
A10: 7 | B10: 10_places | C10: lat | D10: 纬度 | E10: number | F10: N | G10: 34.8100000 | H10: [-90,90] | I10: WGS84/GCJ-02等须与crs一致。
A11: 8 | B11: 10_places | C11: crs | D11: 坐标系 | E11: enum | F11: N | G11: WGS84 | H11: WGS84|GCJ-02|BD-09|pixel | I11: 坐标为空时可为空；存在坐标时必填。
A12: 9 | B12: 10_places | C12: aliases | D12: 别名 | E12: string | F12: N | G12: 别名1；别名2 | I12: 多个别名用分号分隔。
A13: 10 | B13: 10_places | C13: external_poi_id | D13: 外部POI ID | E13: string | F13: N | G13: provider_id | I13: 高德等外部地点ID；注明来源。
A14: 11 | B14: 10_places | C14: indoor_outdoor | D14: 室内外属性 | E14: enum | F14: N | G14: outdoor | H14: indoor|outdoor|mixed|unknown | I14: 用于体验与天气判断。
A15: 12 | B15: 10_places | C15: suggested_stay_min | D15: 建议停留分钟 | E15: integer | F15: N | G15: 90 | H15: >=0 | I15: 首轮可为空；有来源时填写。
A16: 13 | B16: 10_places | C16: description | D16: 简介 | E16: string | F16: N | G16: 简要介绍 | I16: 避免无来源的文化故事。
A17: 14 | B17: 10_places | C17: source_id | D17: 来源ID | E17: string | F17: Y | G17: src_000001 | I17: 关联18_source_records。
A18: 15 | B18: 10_places | C18: validation_status | D18: 校验状态 | E18: enum | F18: Y | G18: candidate | H18: candidate|pending_review|verified|conflict|stale|expired|cancelled|mock|rejected | I18: 候选与已核实必须分开。
A19: 16 | B19: 10_places | C19: verified_at | D19: 核实时间 | E19: datetime | F19: N | G19: 例：2026-10-21T10:00:00+08:00 | H19: ISO 8601 +08:00 | I19: 人工核实时间。
A20: 17 | B20: 10_places | C20: valid_from | D20: 有效期起 | E20: date | F20: N | G20: 例：2026-10-21 | H20: YYYY-MM-DD | I20: 记录适用起始日。
A21: 18 | B21: 10_places | C21: valid_to | D21: 有效期止 | E21: date | F21: N | G21: 例：2026-12-31 | H21: YYYY-MM-DD | I21: 过期后需降级。
A22: 19 | B22: 10_places | C22: reviewer | D22: 核验人 | E22: string | F22: N | G22: 成员3 | I22: 真实负责人或组内代号。
A23: 20 | B23: 10_places | C23: version | D23: 版本 | E23: integer | F23: Y | G23: 1 | H23: >=1 | I23: 每次实质性修改递增。
A24: 21 | B24: 10_places | C24: notes | D24: 备注 | E24: string | F24: N | G24: 待补充说明 | I24: 只写复现所需信息。
A25: 22 | B25: 11_place_entrances | C25: entrance_id | D25: 入口ID | E25: string | F25: Y | G25: ent_000001 | H25: 唯一稳定ID | I25: 入口主键。
A26: 23 | B26: 11_place_entrances | C26: place_id | D26: 地点ID | E26: string | F26: Y | G26: pl_000001 | I26: 关联10_places。
A27: 24 | B27: 11_place_entrances | C27: name | D27: 入口名称 | E27: string | F27: Y | G27: 入口名称 | I27: 官方名称或现场标识。
A28: 25 | B28: 11_place_entrances | C28: entrance_type | D28: 入口类型 | E28: enum | F28: Y | G28: main_entrance | H28: main_entrance|secondary_entrance|area_entrance|exit|unknown | I28: 景区中心点不能代替入口。
A29: 26 | B29: 11_place_entrances | C29: lng | D29: 经度 | E29: number | F29: N | G29: 114.3500000 | H29: [-180,180] | I29: 有坐标时必填。
A30: 27 | B30: 11_place_entrances | C30: lat | D30: 纬度 | E30: number | F30: N | G30: 34.8100000 | H30: [-90,90] | I30: 有坐标时必填。
A31: 28 | B31: 11_place_entrances | C31: crs | D31: 坐标系 | E31: enum | F31: N | G31: WGS84 | H31: WGS84|GCJ-02|BD-09|pixel | I31: 与坐标同时填写。
A32: 29 | B32: 11_place_entrances | C32: is_main_entrance | D32: 是否主入口 | E32: boolean | F32: N | G32: true | H32: true|false|unknown | I32: 未知不要填false。
A33: 30 | B33: 11_place_entrances | C33: access_rules | D33: 通行规则 | E33: string | F33: N | G33: 仅游客入口 | I33: 门禁、员工通道等说明。
A34: 31 | B34: 11_place_entrances | C34: stop_entry_before | D34: 最晚入园 | E34: time | F34: N | G34: 例：20:30 | H34: HH:MM | I34: 必须附带时区。
A35: 32 | B35: 11_place_entrances | C35: open_rule_id | D35: 开放规则ID | E35: string | F35: N | G35: or_000001 | I35: 关联12_open_rules。
A36: 33 | B36: 11_place_entrances | C36: source_id | D36: 来源ID | E36: string | F36: Y | G36: src_000001 | I36: 关联18_source_records。
A37: 34 | B37: 11_place_entrances | C37: validation_status | D37: 校验状态 | E37: enum | F37: Y | G37: candidate | H37: candidate|pending_review|verified|conflict|stale|expired|cancelled|mock|rejected | I37: 候选与已核实分开。
A38: 35 | B38: 11_place_entrances | C38: verified_at | D38: 核实时间 | E38: datetime | F38: N | G38: 例：2026-10-21T10:00:00+08:00 | H38: ISO 8601 +08:00 | I38: 人工核实时间。
A39: 36 | B39: 11_place_entrances | C39: notes | D39: 备注 | E39: string | F39: N | G39: 待补充说明 | I39: 记录冲突或位置精度。
A40: 37 | B40: 12_open_rules | C40: open_rule_id | D40: 规则ID | E40: string | F40: Y | G40: or_000001 | H40: 唯一稳定ID | I40: 规则主键。
...

Sheet 03_首轮目标
A1: 首轮数量目标与实时进度
A2: 候选数和已核实数分开统计。数字目标来自三人/四人分工中的第一轮建议，未给数字的对象按覆盖范围核验。
A4: 数据表 | B4: 首轮对象 | C4: 候选目标下限 | D4: 核实目标下限 | E4: 当前候选数 | F4: 当前已核实数 | G4: 候选进度 | H4: 核实进度 | I4: 状态 | J4: 说明
A5: 10_places | B5: 城市与景区地点候选 | C5: 30 | E5: =COUNTIF('10_places'!O4:O503,"candidate") | F5: =COUNTIF('10_places'!O4:O503,"verified") | G5: =IF(OR(C5="",E5=0),"",E5/C5) | H5: =IF(OR(D5="",F5=0),"",F5/D5) | I5: =IF(AND(C5="",D5=""),"按覆盖核验",IF(COUNTA('10_places'!A4:A503)=0,"待录入",IF(AND(C5<>"",E5>=C5,OR(D5="",F5>=D5)),"达到候选目标","进行中"))) | J5: 30–50个候选是首轮扩展目标；先保证可关联
A6: 11_place_entrances | B6: 重点目的地入口 | C6: 10 | E6: =COUNTIF('11_place_entrances'!M4:M503,"candidate") | F6: =COUNTIF('11_place_entrances'!M4:M503,"verified") | G6: =IF(OR(C6="",E6=0),"",E6/C6) | H6: =IF(OR(D6="",F6=0),"",F6/D6) | I6: =IF(AND(C6="",D6=""),"按覆盖核验",IF(COUNTA('11_place_entrances'!A4:A503)=0,"待录入",IF(AND(C6<>"",E6>=C6,OR(D6="",F6>=D6)),"达到候选目标","进行中"))) | J6: 首轮先采10–15个重点目的地入口
A7: 12_open_rules | B7: 开放与入场规则 | C7: 10 | E7: =COUNTIF('12_open_rules'!Q4:Q503,"candidate") | F7: =COUNTIF('12_open_rules'!Q4:Q503,"verified") | G7: =IF(OR(C7="",E7=0),"",E7/C7) | H7: =IF(OR(D7="",F7=0),"",F7/D7) | I7: =IF(AND(C7="",D7=""),"按覆盖核验",IF(COUNTA('12_open_rules'!A4:A503)=0,"待录入",IF(AND(C7<>"",E7>=C7,OR(D7="",F7>=D7)),"达到候选目标","进行中"))) | J7: 先覆盖已有入口的重点目的地
A8: 13_programs | B8: 两大重点景区节目 | E8: =COUNTIF('13_programs'!J4:J503,"candidate") | F8: =COUNTIF('13_programs'!J4:J503,"verified") | G8: =IF(OR(C8="",E8=0),"",E8/C8) | H8: =IF(OR(D8="",F8=0),"",F8/D8) | I8: =IF(AND(C8="",D8=""),"按覆盖核验",IF(COUNTA('13_programs'!A4:A503)=0,"待录入",IF(AND(C8<>"",E8>=C8,OR(D8="",F8>=D8)),"达到候选目标","进行中"))) | J8: 覆盖两大景区代表性试采节目
A9: 14_show_sessions | B9: 已公布且日期明确的场次 | E9: =COUNTIF('14_show_sessions'!N4:N503,"candidate") | F9: =COUNTIF('14_show_sessions'!N4:N503,"verified") | G9: =IF(OR(C9="",E9=0),"",E9/C9) | H9: =IF(OR(D9="",F9=0),"",F9/D9) | I9: =IF(AND(C9="",D9=""),"按覆盖核验",IF(COUNTA('14_show_sessions'!A4:A503)=0,"待录入",IF(AND(C9<>"",E9>=C9,OR(D9="",F9>=D9)),"达到候选目标","进行中"))) | J9: 覆盖首轮节目；不得用常规节目单推算未来场次
A10: 15_food_items | B10: 开封特色菜品候选 | C10: 20 | E10: =COUNTIF('15_food_items'!I4:I503,"candidate") | F10: =COUNTIF('15_food_items'!I4:I503,"verified") | G10: =IF(OR(C10="",E10=0),"",E10/C10) | H10: =IF(OR(D10="",F10=0),"",F10/D10) | I10: =IF(AND(C10="",D10=""),"按覆盖核验",IF(COUNTA('15_food_items'!A4:A503)=0,"待录入",IF(AND(C10<>"",E10>=C10,OR(D10="",F10>=D10)),"达到候选目标","进行中"))) | J10: 首轮建议20–25种
A11: 16_food_vendors | B11: 经核实商家候选 | C11: 30 | E11: =COUNTIF('16_food_vendors'!P4:P503,"candidate") | F11: =COUNTIF('16_food_vendors'!P4:P503,"verified") | G11: =IF(OR(C11="",E11=0),"",E11/C11) | H11: =IF(OR(D11="",F11=0),"",F11/D11) | I11: =IF(AND(C11="",D11=""),"按覆盖核验",IF(COUNTA('16_food_vendors'!A4:A503)=0,"待录入",IF(AND(C11<>"",E11>=C11,OR(D11="",F11>=D11)),"达到候选目标","进行中"))) | J11: 首轮建议30–50家候选
A12: 17_vendor_foods | B12: 菜品—商家关系候选 | C12: 30 | E12: =COUNTIF('17_vendor_foods'!G4:G503,"candidate") | F12: =COUNTIF('17_vendor_foods'!G4:G503,"verified") | G12: =IF(OR(C12="",E12=0),"",E12/C12) | H12: =IF(OR(D12="",F12=0),"",F12/D12) | I12: =IF(AND(C12="",D12=""),"按覆盖核验",IF(COUNTA('17_vendor_foods'!A4:A503)=0,"待录入",IF(AND(C12<>"",E12>=C12,OR(D12="",F12>=D12)),"达到候选目标","进行中"))) | J12: 首轮建议30–50条关系候选
A13: 18_source_records | B13: 来源证据记录 | C13: 1 | E13: =COUNTIF('18_source_records'!M4:M503,"candidate") | F13: =COUNTIF('18_source_records'!M4:M503,"verified") | G13: =IF(OR(C13="",E13=0),"",E13/C13) | H13: =IF(OR(D13="",F13=0),"",F13/D13) | I13: =IF(AND(C13="",D13=""),"按覆盖核验",IF(COUNTA('18_source_records'!A4:A503)=0,"待录入",IF(AND(C13<>"",E13>=C13,OR(D13="",F13>=D13)),"达到候选目标","进行中"))) | J13: 每条首批候选至少有一个可定位来源
A14: 19_change_log | B14: 变更记录 | E14: =COUNTIF('19_change_log'!N4:N503,"candidate") | F14: =COUNTIF('19_change_log'!N4:N503,"verified") | G14: =IF(OR(C14="",E14=0),"",E14/C14) | H14: =IF(OR(D14="",F14=0),"",F14/D14) | I14: =IF(AND(C14="",D14=""),"按覆盖核验",IF(COUNTA('19_change_log'!A4:A503)=0,"待录入",IF(AND(C14<>"",E14>=C14,OR(D14="",F14>=D14)),"达到候选目标","进行中"))) | J14: 有修改、合并或降级时必须记录
A15: 22_media_assets | B15: 图片、视频等媒体素材 | E15: =COUNTIF('22_media_assets'!AH4:AH503,"candidate") | F15: =COUNTIF('22_media_assets'!AH4:AH503,"verified") | I15: 按覆盖核验 | J15: 成员1负责地点/节目/入口媒体，成员4负责菜品/商家媒体；一个文件一行
A16: 23_media_relations | B16: 媒体与业务对象关联 | E16: =COUNTIF('23_media_relations'!I4:I503,"candidate") | F16: =COUNTIF('23_media_relations'!I4:I503,"verified") | I16: 按覆盖核验 | J16: 同一媒体可关联多个对象；主媒体、排序和用途必须可追溯

Sheet 04_现有资产接入
A1: 现有资产接入判断
A2: 现有采集包可提供种子数据，但旧字段不能直接替代新项目事实。接入时必须重新标记状态、来源、有效期和跨表ID。
A4: 当前资产 | B4: 现有规模 | C4: 建议目标表 | D4: 可复用部分 | E4: 主要缺口 | F4: 接入动作
A5: 现有 scenics.csv | B5: 5个景区摘要 | C5: 10_places | D5: 可作为景区级种子候选 | E5: 缺少城市景点、夜市、餐饮街区和交通枢纽样本 | F5: 仅导入为candidate，补齐30–50个候选
A6: 现有 entrances.csv | B6: 10条入口/区入口名称 | C6: 11_place_entrances | D6: 可建立入口候选 | E6: 缺精确入口坐标，precise_navigation_eligible=false | F6: 由成员3逐条核验真实入口和坐标
A7: 现有 information_facts.csv | B7: 67条带来源字段主张 | C7: 12_open_rules | D7: 可提取开放时间、票价、预约规则候选 | E7: 同字段存在冲突，不能直接生成确定规则 | F7: 保留多个来源，状态标pending_review/conflict
A8: 现有清园/万岁山节目资料 | B8: 清园153个节目；万岁山41条介绍 | C8: 13_programs | D8: 可整理节目、舞台和说明候选 | E8: 万岁山未取得日期明确场次；舞台坐标不足 | F8: 成员1补场次，成员3补舞台地点关联
A9: 现有 shows.csv | B9: 463个2026-10-20开始时刻 | C9: 14_show_sessions | D9: 结构可直接转化为独立场次 | E9: 全部缺结束时间，仅为历史日期快照 | F9: 作为样例/历史快照，不作为未来场次保证
A10: 现有食品数据 | B10: 无 | C10: 15_food_items / 16_food_vendors / 17_vendor_foods | D10: 暂无 | E10: 菜品、商家、供应关系均缺失 | F10: 由成员4按首轮目标新建候选池
A11: 现有 sources.csv | B11: 72个来源/响应 | C11: 18_source_records | D11: 可建立来源证据基线 | E11: 授权状态不完整、部分页面抓取失败 | F11: 建立rights_status和证据路径，不默认可再发布
A12: 现有 data_issues.csv / validation报告 | B12: 60条问题项，9项结构校验 | C12: 19_change_log + 校验规则 | D12: 可复用异常分类和结构校验思路 | E12: 旧表结构与本轮10张核心表不同 | F12: 迁移为统一问题代码并保留变更历史
A15: 本次填写后的数据规模（2026-10-22初筛）
A16: 数据表 | B16: 总记录 | C16: 候选 | D16: 待审/冲突/过期 | E16: 已核实 | F16: 初筛结论
A17: 10_places | B17: 16 | C17: 8 | D17: 8 | E17: 0 | F17: 已有候选，但尚无verified记录
A18: 11_place_entrances | B18: 20 | C18: 18 | D18: 2 | E18: 0 | F18: 已有候选，但尚无verified记录
A19: 12_open_rules | B19: 19 | C19: 6 | D19: 13 | E19: 0 | F19: 已有候选，但尚无verified记录
A20: 13_programs | B20: 98 | C20: 93 | D20: 5 | E20: 0 | F20: 已有候选，但尚无verified记录
A21: 14_show_sessions | B21: 0 | C21: 0 | D21: 0 | E21: 0 | F21: 空表，存在关键覆盖缺口
A22: 15_food_items | B22: 26 | C22: 26 | D22: 0 | E22: 0 | F22: 已有候选，但尚无verified记录
A23: 16_food_vendors | B23: 32 | C23: 12 | D23: 20 | E23: 0 | F23: 已有候选，但尚无verified记录
A24: 17_vendor_foods | B24: 48 | C24: 42 | D24: 6 | E24: 0 | F24: 已有候选，但尚无verified记录
A25: 18_source_records | B25: 116 | C25: 112 | D25: 4 | E25: 0 | F25: 已有候选，但尚无verified记录
A26: 19_change_log | B26: 464 | C26: 0 | D26: 464 | E26: 0 | F26: 已有候选，但尚无verified记录

Sheet 10_places
A1: 地点主表 places
A2: 仅收集候选与核实数据；不得把格式正确误判为事实真实。导入前请运行校验脚本。
A3: place_id | B3: name | C3: place_type | D3: parent_place_id | E3: address | F3: lng | G3: lat | H3: crs | I3: aliases | J3: external_poi_id | K3: indoor_outdoor | L3: suggested_stay_min | M3: description | N3: source_id | O3: validation_status | P3: verified_at | Q3: valid_from | R3: valid_to | S3: reviewer | T3: version | U3: notes
A4: pl_000001 | B4: 清明上河园 | C4: scenic_spot | E4: 河南省开封市龙亭西路5号 | I4: 清园 | K4: unknown | M4: 国家5A级旅游景区，以《清明上河图》为蓝本1:1复原的大型宋代历史文化主题公园，占地超过540亩。 | N4: src_000004 | O4: candidate | S4: 成员1 | T4: 1 | U4: 官网地址与介绍；官网另提到端门、丹凤门等门名，未明确为游客入口；坐标未取得，待成员3核验。
A5: pl_000002 | B5: 万岁山武侠城 | C5: scenic_spot | E5: 河南省开封市龙亭区东京大道中段 | I5: 万岁山；大宋武侠城 | K5: unknown | M5: 以武侠文化为核心的景区，包含江湖狂欢艺术区、武侠影视街区、山水田园区、仙侠奇境区、水浒区、十里洋场区等主题区。 | N5: src_000010 | O5: candidate | S5: 成员1 | T5: 1 | U5: 官网首页地址；入口名单见 src_000011；坐标未取得，待成员3核验；官网首页标注 8:00~21:00 检票时间。
A6: pl_000003 | B6: 开封府 | C6: scenic_spot | E6: 河南省开封市鼓楼区包公东湖北岸 | I6: 开封府景区；南衙 | K6: unknown | M6: 国家4A级旅游景区，北宋管理国都及京畿地区的重要机构复原，被誉为“天下首府”。 | N6: src_000015 | O6: candidate | S6: 成员1 | T6: 1 | U6: 官网地址；日间/夜游时间与票价见 src_000015/000016；入口只确认府门，其他入口待核验；坐标待成员3。
A7: pl_000004 | B7: 龙亭景区 | C7: scenic_spot | E7: 开封市宋都御街北段 | I7: 龙亭公园；开封市龙亭景区 | K7: unknown | M7: 国家AAAA级旅游景区，集皇家园林、历史文物和秀美风光于一体，历史上曾是六个朝代的皇宫所在地，距今1200多年。 | N7: src_000019 | O7: candidate | S7: 成员1 | T7: 1 | U7: 官网地址/介绍；开放时间、票价、入口见 src_000018；坐标待成员3；节目时间待公众号节目单。
A8: pl_000005 | B8: 大相国寺 | C8: scenic_spot | E8: 河南省开封市鼓楼区自由路西段36号 | I8: 相国寺；开封大相国寺 | K8: unknown | M8: 中国汉传佛教十大名寺之一，国家4A级旅游景区，始建于北齐天保六年（555年），北宋时期为皇家寺院。 | N8: src_000023 | O8: pending_review | S8: 成员1 | T8: 1 | U8: 官方官网域名已失效；政府名录确认4A（src_000021）、省退役军人事务厅确认鼓楼区（src_000022）；地址/时间/票价来自OTA（src_000023/000024），待官方核实。入口/坐标未找到官方来源。
A9: pl_000006 | B9: 铁塔景区 | C9: scenic_spot | E9: 河南省开封市顺河回族区北门大街210号 | I9: 铁塔公园；开封铁塔 | K9: unknown | M9: 国家4A级旅游景区，以现存铁塔（开宝寺塔）为核心的名胜古迹公园；铁塔为全国重点文物保护单位，高55.08米、八角十三层。 | N9: src_000026 | O9: pending_review | S9: 成员1 | T9: 1 | U9: 政府名录确认4A（src_000021）；地址/活动来自本地宝（src_000027）；时间/票价来自河南交通广播转述的景区公告（src_000026）；官网 kaifengtieta.com 无法访问，待官方核实。
A10: pl_000007 | B10: 中国翰园碑林 | C10: scenic_spot | E10: 河南省开封市龙亭区龙亭北路15号 | I10: 翰园碑林；中国翰园 | K10: unknown | M10: 国家4A级旅游景区，集书画碑刻艺术与古典园林建筑于一体的文化园林，占地120亩，刻碑4000多块。 | N10: src_000030 | O10: candidate | S10: 成员1 | T10: 1 | U10: 官网地址/电话/开放时间（src_000030）；介绍（src_000028）；入口（src_000029）；票价来自OTA（src_000031），待官方；坐标待成员3。
A11: pl_000008 | B11: 包公祠 | C11: scenic_spot | E11: 河南省开封市鼓楼区向阳路1号 | I11: 开封包公祠；包公祠景区 | K11: unknown | M11: 国家4A级旅游景区，纪念北宋名臣包拯的祠堂，位于包公湖西畔，占地1公顷多，由大殿、二殿、东西配殿、半壁廊、碑亭组成。 | N11: src_000032 | O11: candidate | S11: 成员1 | T11: 1 | U11: 政府/旅游网确认4A、地址、介绍（src_000032/000034）；季节时间和线上票价来自大河票务（src_000033），待官方；入口/坐标待核实。
A12: pl_000009 | B12: 天波杨府 | C12: scenic_spot | E12: 河南省开封市龙亭区龙亭北路14号 | I12: 开封天波杨府；天波府 | K12: unknown | M12: 北宋抗辽名将杨业府邸的仿宋重建建筑群，国家4A级旅游景区，由中院府衙、西院花园、东院演兵场组成。 | N12: src_000035 | O12: pending_review | S12: 成员1 | T12: 1 | U12: 政府名录确认4A（src_000021）、省退役军人事务厅确认龙亭区（src_000036）；地址/时间/介绍来自去哪儿（src_000035）；电话/旧信息来自河南景区详情（src_000037）；官网多个候选域名均无法解析；坐标/入口待核实。
A13: pl_000010 | B13: 开封城墙 | C13: scenic_spot | E13: 河南省开封市龙亭区大梁路与内顺城路交叉口 | I13: 开封城墙景区；宋都城墙 | K13: mixed | M13: 全国重点文物保护单位，开封城墙景区开放大梁门至安远门段，含古马道遗址、大梁门、玻璃栈道等。 | N13: src_000038 | O13: candidate | S13: 成员1 | T13: 1 | U13: 官网游玩指南：夏8:30-22:00/冬8:30-21:30，票价40/20，四个登城口；政府A级名录为3A，另有2024年升4A说法待核实；坐标待成员3。
A14: pl_000011 | B14: 山陕甘会馆 | C14: scenic_spot | E14: 河南省开封市龙亭区徐府街85号 | I14: 开封山陕甘会馆 | K14: unknown | M14: 全国重点文物保护单位，清代晋陕甘三省商帮会馆，以砖、石、木雕“三绝”著称，现存照壁、戏楼、牌楼、正殿等。 | N14: src_000040 | O14: candidate | S14: 成员1 | T14: 1 | U14: 政府页确认地址/介绍（src_000040）、省退役军人事务厅确认龙亭区/优待免票（src_000041）；开放时间和票价来自大河票务（src_000042），待官方；政府A级名录为2A，第三方称4A，待核实；入口/坐标待补。
A15: pl_000012 | B15: 延庆观 | C15: scenic_spot | E15: 河南省开封市鼓楼区观前街53号 | I15: 开封延庆观；重阳观 | K15: unknown | M15: 全国重点文物保护单位，元代玉皇阁为开封现存唯一元代建筑，与北京白云观、四川常道观并称中国三大名观。 | N15: src_000044 | O15: pending_review | S15: 成员1 | T15: 1 | U15: 政府A级名录为2A（src_000021）；忆起追迹称2012年AAA，待核实；地址/时间/票价来自忆起追迹/要出发（src_000043/000045），待官方；入口/坐标待补。
... A19: pl_000016 | B19: 汴梁小宋城 | C19: food_street | E19: 河南省开封市大梁路西段（郑开大道与夷山大街交汇处附近） | I19: 小宋城；开封小宋城 | K19: mixed | M19: 由原东京艺术中心改造的文商旅综合体，约5万平方米，其中2万平方米为特色民俗餐饮街区，汇集开封及各地小吃，并有《千回大宋》演出。 | N19: src_000057 | O19: pending_review | S19: 成员1 | T19: 1 | U19: 媒体/OTA：面积、餐饮街区、演出；地址来自永安/大河（src_000058/000059）；区划有金明区/龙亭区说法；官方独立网站未找到；坐标/入口待补。

Sheet 11_place_entrances
A1: 入口表 place_entrances
A2: 仅收集候选与核实数据；不得把格式正确误判为事实真实。导入前请运行校验脚本。
A3: entrance_id | B3: place_id | C3: name | D3: entrance_type | E3: lng | F3: lat | G3: crs | H3: is_main_entrance | I3: access_rules | J3: stop_entry_before | K3: open_rule_id | L3: source_id | M3: validation_status | N3: verified_at | O3: notes
A4: ent_000001 | B4: pl_000001 | C4: 迎宾门 | D4: main_entrance | H4: true | I4: 游客入口；东大门；每天9:00开园迎宾仪式地点 | K4: or_000001 | L4: src_000004 | M4: candidate | O4: 官方称东大门、开园迎宾；坐标为空白，待成员3核验。
A5: ent_000002 | B5: pl_000001 | C5: 金水门 | D5: secondary_entrance | H5: unknown | I5: 游客入口；西门 | K5: or_000001 | L5: src_000004 | M5: candidate | O5: 官方称与迎宾门对应的西门；是否主入口未明确；坐标待核验。
A6: ent_000003 | B6: pl_000002 | C6: 西大门 | D6: main_entrance | H6: unknown | I6: 游客入口；官方公告建议优先从东门、西门、中门进入（客流量较小） | K6: or_000002 | L6: src_000011 | M6: candidate | O6: 官方2025-12-19《一个景区有七个入口》文章；名单来自文中地图图片；坐标待成员3核验。
A7: ent_000004 | B7: pl_000002 | C7: 南大门 | D7: main_entrance | H7: unknown | I7: 游客入口；园区大门之一 | K7: or_000002 | L7: src_000011 | M7: candidate | O7: 官方2025-12-19《一个景区有七个入口》文章；名单来自文中地图图片；坐标待成员3核验。
A8: ent_000005 | B8: pl_000002 | C8: 中门 | D8: main_entrance | H8: unknown | I8: 游客入口；官方公告建议优先从东门、西门、中门进入（客流量较小） | K8: or_000002 | L8: src_000011 | M8: candidate | O8: 官方2025-12-19《一个景区有七个入口》文章；名单来自文中地图图片；坐标待成员3核验。
A9: ent_000006 | B9: pl_000002 | C9: 东大门 | D9: main_entrance | H9: unknown | I9: 游客入口；官方公告建议优先从东门、西门、中门进入（客流量较小） | K9: or_000002 | L9: src_000011 | M9: candidate | O9: 官方2025-12-19《一个景区有七个入口》文章；名单来自文中地图图片；坐标待成员3核验。
A10: ent_000007 | B10: pl_000002 | C10: 水浒区入口 | D10: area_entrance | H10: unknown | I10: 游客入口；按行程选择最近入口 | K10: or_000002 | L10: src_000011 | M10: candidate | O10: 官方2025-12-19《一个景区有七个入口》文章；名单来自文中地图图片；坐标待成员3核验。
A11: ent_000008 | B11: pl_000002 | C11: 仙侠区入口 | D11: area_entrance | H11: unknown | I11: 游客入口；按行程选择最近入口 | K11: or_000002 | L11: src_000011 | M11: candidate | O11: 官方2025-12-19《一个景区有七个入口》文章；名单来自文中地图图片；坐标待成员3核验。
A12: ent_000009 | B12: pl_000002 | C12: 江湖艺术区入口 | D12: area_entrance | H12: unknown | I12: 游客入口；按行程选择最近入口 | K12: or_000002 | L12: src_000011 | M12: candidate | O12: 官方2025-12-19《一个景区有七个入口》文章；名单来自文中地图图片；坐标待成员3核验。
A13: ent_000010 | B13: pl_000003 | C13: 府门 | D13: main_entrance | H13: true | I13: 游客入口；凭身份证刷府门入口闸机入园 | K13: or_000003 | L13: src_000016 | M13: candidate | O13: 官方预约购票页明确“府门入口处闸机”；其他入口未在官网找到，待核验。
A14: ent_000011 | B14: pl_000004 | C14: 南门 | D14: main_entrance | H14: unknown | I14: 游客入口；南门及相邻停车场 | K14: or_000005 | L14: src_000018 | M14: candidate | O14: 官方游园指南明确南门、北门均可进入；坐标为空白，待成员3核验。
A15: ent_000012 | B15: pl_000004 | C15: 北门 | D15: main_entrance | H15: unknown | I15: 游客入口；北门及相邻停车场 | K15: or_000005 | L15: src_000018 | M15: candidate | O15: 官方游园指南明确南门、北门均可进入；坐标为空白，待成员3核验。
... A23: ent_000020 | B23: pl_000010 | C23: 安远门登城口 | D23: secondary_entrance | H23: unknown | I23: 游客登城口；安远门 | K23: or_000013 | L23: src_000038 | M23: candidate | O23: 官方游玩指南列出；坐标待成员3。

Sheet 12_open_rules
A1: 开放与入场规则 open_rules
A2: 仅收集候选与核实数据；不得把格式正确误判为事实真实。导入前请运行校验脚本。
A3: open_rule_id | B3: place_id | C3: rule_name | D3: rule_type | E3: effective_from | F3: effective_to | G3: weekdays | H3: open_time | I3: close_time | J3: last_entry_time | K3: timezone | L3: ticket_scope | M3: reservation_required | N3: reentry_allowed | O3: special_rules | P3: source_id | Q3: validation_status | R3: verified_at | S3: version | T3: notes
A4: or_000001 | B4: pl_000001 | C4: 常规开放时间 | D4: daily | G4: 1;2;3;4;5;6;7 | H4: 09:00 | I4: 22:00 | K4: Asia/Shanghai (+08:00) | L4: 白天门票（全价票/半价票） | M4: true | N4: unknown | O4: 雨雪等天气节目可能临时更改或停演，以景区当天广播预报和微信演出通知为准；半价票适用6-18岁未成年人、全日制学生、60岁以上老人，凭有效证件。 | P4: src_000002 | Q4: pending_review | S4: 1 | T4: 开放时间09:00-22:00来自官网FAQ；实名制分时预约见 src_000007；票价全价120元/半价60元（12表无价格字段，暂记备注）；二次入园冲突：商品详情称仅限购买当天使用，2026-10-05新闻称一票游3天，待核实。
A5: or_000002 | B5: pl_000002 | C5: 常规检票/开放时间（官网首页） | D5: daily | G5: 1;2;3;4;5;6;7 | H5: 08:00 | I5: 23:00 | J5: 21:00 | K5: Asia/Shanghai (+08:00) | L5: 成人票、儿童/学生/老人/退役军人票、大马戏票、汴河游船联票、城墙观光车联票（官方公众号购票入口） | M5: unknown | N5: true | O5: 官网首页标注“8:00~21:00 检票时间”；官方公众号购票入口显示：万岁山武侠城入园时间08:00-21:00，园区开放至23:00；自核销当日起3个自然日内不限次入园；下单后不支持改期。停车换乘：复兴三号换乘停车场周一至周五 8:00-22:00，周末及节假日 8:00-23:00；景区门口提供免费接驳车（约每15分钟一班，招手即停）。 | P5: src_000013 | Q5: pending_review | S5: 1 | T5: 官网首页：8:00~21:00 检票时间。官方公众号“购票”入口跳转美团页面：列表页显示08:00-23:00开放、最晚21:00入园；成人票详情显示万岁山入园时间08:00-21:00、自核销当日起3个自然日内不限次入园、无需换票、未使用可随时全额退款、过期后1天自动退款、下单后不支持改期。票价：成人100起/优惠50起/大马戏118或80起/汴河游船联票128或68起/城墙观光车联票120或70起。预约规则未展示。
A6: or_000003 | B6: pl_000003 | C6: 日场常规（官网参观导览） | D6: daily | G6: 1;2;3;4;5;6;7 | H6: 07:30 | I6: 19:00 | J6: 17:30 | K6: Asia/Shanghai (+08:00) | L6: 日间票（成人65元/学生32元） | M6: unknown | N6: unknown | O6: 冬季 7:30–17:30；官网另有夏季 7:00–19:00、入园时间 07:00–19:00（冬季 7:30–18:30）等口径，存在冲突；夜游 17:00 开售、22:00 闭园；节目变动以当天预告为准。 | P6: src_000016 | Q6: conflict | S6: 1 | T6: 官网首页：7:30–19:00（春、夏、秋）、7:30–17:30（冬）；预约购票页：7:30–22:00、17:30停止入园；参观指南：夏季7:00–19:00、冬季7:30–18:30。先按日场7:30–19:00、17:30停止入园记录，冲突待核实。
A7: or_000004 | B7: pl_000003 | C7: 夜游《南衙千秋月》 | D7: daily | G7: 1;2;3;4;5;6;7 | H7: 17:00 | I7: 22:00 | K7: Asia/Shanghai (+08:00) | L7: 夜游票（成人90元/半价45元，全天不限次入园） | M7: unknown | N7: true | O7: 各类优惠证件不可使用，需购全价票入园；夜游22:00闭园。 | P7: src_000015 | Q7: candidate | S7: 1 | T7: 官网首页/预约购票页：夜游17:00开售、22:00闭园，门票90元/半价45元，全天不限次入园；是否每日开放待确认。
A8: or_000005 | B8: pl_000004 | C8: 常规开放时间（官网游园指南） | D8: daily | G8: 1;2;3;4;5;6;7 | H8: 08:00 | I8: 21:30 | K8: Asia/Shanghai (+08:00) | L8: 全票45元/半价22元（节会期间按实际票价） | M8: unknown | N8: unknown | O8: 节会期间门票按实际票价；南门、北门均可入园；节目单需关注龙亭景区公众号，官网未列具体时间。 | P8: src_000018 | Q8: candidate | S8: 1 | T8: 官网游园指南：开放08:00-21:30，全票45/半价22；免票/半票规则见页面；节目单需公众号。
A9: or_000006 | B9: pl_000005 | C9: 夏季开放时间（OTA口径，待官方核实） | D9: daily | G9: 1;2;3;4;5;6;7 | H9: 08:00 | I9: 18:00 | J9: 18:00 | K9: Asia/Shanghai (+08:00) | L9: 成人40元/半价20元（官方小程序） | M9: unknown | N9: unknown | O9: 官方小程序：无需取票，二维码/身份证刷闸机入园；门票仅限当日有效；未使用可随时退，刷码后不退；半价票适用6-18岁未成年人、全日制学生、教师等（凭证件）。 | P9: src_000051 | Q9: candidate | S9: 1 | T9: 官方小程序购票须知：开放8:00-18:00，票价40/20，当日有效。
A10: or_000007 | B10: pl_000005 | C10: 冬季开放时间（OTA口径，待官方核实） | D10: date_range | E10: 2026-11-01 | F10: 2027-03-10 | G10: 1;2;3;4;5;6;7 | H10: 08:00 | I10: 18:00 | J10: 17:00 | K10: Asia/Shanghai (+08:00) | L10: 成人约40元/优待约20元（OTA线上37.5/19，待官方） | M10: unknown | N10: unknown | O10: 夏季 3/11-10/31 08:00-18:30，18:00停止入园；春秋季 08:00-18:00、17:30停止入园（去哪儿口径）；以景区当日公告为准。 | P10: src_000023 | Q10: expired | S10: 1 | T10: 官方小程序统一8:00-18:00；原OTA冬季规则作废。
A11: or_000008 | B11: pl_000006 | C11: 常规营业时间（景区公告，待官方核实） | D11: daily | G11: 1;2;3;4;5;6;7 | H11: 08:30 | I11: 21:00 | K11: Asia/Shanghai (+08:00) | L11: 成人30元/半价15元（官方门票公示牌） | M11: unknown | N11: unknown | O11: 节假日/特殊活动另行通知；铁塔光影秀已暂停演出，恢复时间另行通知；登塔另收费/是否开放待核实。 | P11: src_000055 | Q11: candidate | S11: 1 | T11: 景区客服回复：当前8:30-21:00；《五灵寻禅》10:00-17:00，周一NPC休息；门票公示牌全价30/半价15；节目以当天广播为准。
A12: or_000009 | B12: pl_000007 | C12: 常规开放时间（官网页脚） | D12: daily | G12: 1;2;3;4;5;6;7 | H12: 08:00 | I12: 22:00 | K12: Asia/Shanghai (+08:00) | L12: 成人40元/优待20元（OTA口径，待官方） | M12: unknown | N12: unknown | O12: 菊花文化节、春节庙会等节会期间活动和时间另行公告；南大门、北大门均可入园。 | P12: src_000030 | Q12: candidate | S12: 1 | T12: 官网全站页脚：开放8:00-22:00；票价来自大河票务（成人40/优待20），待官方；第三方称21:00停止入园，官网未写。
A13: or_000010 | B13: pl_000008 | C13: 春夏秋季开放时间（OTA口径，待官方） | D13: date_range | E13: 2026-04-01 | F13: 2026-10-31 | G13: 1;2;3;4;5;6;7 | H13: 07:00 | I13: 19:00 | K13: Asia/Shanghai (+08:00) | L13: 成人线上27元/门市约30元（OTA口径，待官方） | M13: unknown | N13: unknown | O13: 冬季 11/1-3/31 07:30-17:30；政府/旅游网旧页面写7:00-19:00、门票20元；以景区当日公告为准。 | P13: src_000033 | Q13: pending_review | S13: 1 | T13: 大河票务2025-06-05；官网 kfbgc.cn 返回403打不开；政府/旅游网信息较旧。
A14: or_000011 | B14: pl_000008 | C14: 冬季开放时间（OTA口径，待官方） | D14: date_range | E14: 2026-11-01 | F14: 2027-03-31 | G14: 1;2;3;4;5;6;7 | H14: 07:30 | I14: 17:30 | K14: Asia/Shanghai (+08:00) | L14: 成人线上27元/门市约30元（OTA口径，待官方） | M14: unknown | N14: unknown | O14: 春夏秋季 4/1-10/31 07:00-19:00；政府/旅游网旧页面写7:00-19:00、门票20元；以景区当日公告为准。 | P14: src_000033 | Q14: pending_review | S14: 1 | T14: 大河票务2025-06-05；官网 kfbgc.cn 返回403打不开；政府/旅游网信息较旧。
A15: or_000012 | B15: pl_000009 | C15: 常规开放时间（OTA口径，待官方） | D15: daily | G15: 1;2;3;4;5;6;7 | H15: 08:00 | I15: 22:00 | J15: 21:30 | K15: Asia/Shanghai (+08:00) | L15: 成人约30-40元/优待约20元（OTA口径不一致，待官方） | M15: unknown | N15: unknown | O15: 去哪儿标08:00-22:00、21:30停止入园；其他平台有08:00-18:30、夜游延至22:00等口径；以景区当日公告为准。 | P15: src_000035 | Q15: pending_review | S15: 1 | T15: 官网 tianboyangfu.com、tianbo.kf.cn、tbyf.cn 均无法解析；时间来自去哪儿/其他OTA，待官方核实。
A16: or_000013 | B16: pl_000010 | C16: 常规开放时间（官网游玩指南） | D16: daily | G16: 1;2;3;4;5;6;7 | H16: 08:30 | I16: 22:00 | K16: Asia/Shanghai (+08:00) | L16: 全价40元/半价20元 | M16: unknown | N16: unknown | O16: 冬季 08:30-21:30；季节起止以景区公告为准；四个登城口开放时间可能不同；《微梦大梁门》是否另收费，官网未写。 | P16: src_000038 | Q16: candidate | S16: 1 | T16: 官网游玩指南：夏8:30-22:00，冬8:30-21:30；票价40/20；登城口四个；微梦/古马道为景区内影片。
A17: or_000014 | B17: pl_000011 | C17: 常规开放时间（OTA口径，待官方） | D17: daily | G17: 1;2;3;4;5;6;7 | H17: 08:00 | I17: 18:00 | K17: Asia/Shanghai (+08:00) | L17: 成人约22-25元（OTA口径，待官方） | M17: unknown | N17: unknown | O17: 冬季约 08:00-17:30；季节起止和票价以景区当日公告为准；优待证持证人免门票（省退役军人事务厅）。 | P17: src_000042 | Q17: pending_review | S17: 1 | T17: 大河票务：全年08:00-18:00/08:00-17:30；政府页未给时间；待官方核实。
A18: or_000015 | B18: pl_000012 | C18: 常规开放时间（网络资料，待官方） | D18: daily | G18: 1;2;3;4;5;6;7 | H18: 08:00 | I18: 18:30 | K18: Asia/Shanghai (+08:00) | L18: 成人约15-35元（口径不一，待官方） | M18: unknown | N18: unknown | O18: 另有09:00-17:30口径；票价有15/30/35三种说法；以景区当日公告为准。 | P18: src_000043 | Q18: pending_review | S18: 1 | T18: 忆起追迹/要出发写8:00-18:30；相约久久/百度写9:00-17:30；无独立官网，待官方核实。
A19: or_000016 | B19: pl_000013 | C19: 夜市营业时间（平台口径，待现场核实） | D19: daily | G19: 1;2;3;4;5;6;7 | H19: 10:00 | I19: 22:00 | K19: Asia/Shanghai (+08:00) | L19: 免费进入（摊位消费） | M19: unknown | N19: unknown | O19: 携程标全年10:00-22:00；实际夜市约傍晚开始至午夜，以现场摊位为准。 | P19: src_000049 | Q19: pending_review | S19: 1 | T19: 携程页面；实际营业时间与平台标注可能不同。
A20: or_000017 | B20: pl_000014 | C20: 夜市营业时间（第三方口径，待现场核实） | D20: daily | G20: 1;2;3;4;5;6;7 | H20: 17:30 | I20: 23:30 | K20: Asia/Shanghai (+08:00) | L20: 免费进入（摊位消费） | M20: unknown | N20: unknown | O20: 百家号写“天黑而聚，凌晨而散”；第三方攻略称17:30-23:30，早餐约6:00-9:30；以现场摊位为准。 | P20: src_000050 | Q20: pending_review | S20: 1 | T20: 百家号没有精确时间；17:30-23:30来自第三方攻略口径，待现场核实。
A21: or_000018 | B21: pl_000015 | C21: 夜市营业时间（第三方口径，待现场核实） | D21: daily | G21: 1;2;3;4;5;6;7 | H21: 18:30 | I21: 01:00 | K21: Asia/Shanghai (+08:00) | L21: 免费进入（摊位消费） | M21: unknown | N21: unknown | O21: 跨日营业（18:30-次日1:00）；实际收摊时间以摊位为准；本地宝未写具体时间，时间为第三方攻略口径。 | P21: src_000056 | Q21: pending_review | S21: 1 | T21: 第三方攻略/百度百科称18:30-次日1:00；本地宝只写地址/规模；待现场核实。
A22: or_000019 | B22: pl_000016 | C22: 营业时间（第三方口径，待官方） | D22: daily | G22: 1;2;3;4;5;6;7 | H22: 10:00 | I22: 23:30 | K22: Asia/Shanghai (+08:00) | L22: 免费入场（餐饮/演出另付） | M22: unknown | N22: unknown | O22: 《千回大宋》每晚20:00-21:20，票面188/288元；节假日/演出调整以现场为准。 | P22: src_000059 | Q22: pending_review | S22: 1 | T22: 第三方平台称10:00-23:30；永安页面未列具体时间；待官方核实。

Sheet 13_programs
A1: 节目表 programs
A2: 仅收集候选与核实数据；不得把格式正确误判为事实真实。导入前请运行校验脚本。
A3: program_id | B3: park_place_id | C3: stage_place_id | D3: name | E3: category | F3: description | G3: arrival_buffer_min | H3: ticket_scope | I3: source_id | J3: validation_status | K3: valid_from | L3: valid_to | M3: reviewer | N3: version | O3: notes
A4: prg_000001 | B4: pl_000001 | D4: 包公迎宾 | E4: performance | F4: 开封府尹包拯奉旨领文武百官，设皇家仪仗，行开园大典，迎四海宾客。 | H4: 待核实 | I4: src_000002 | J4: candidate | M4: 成员1 | N4: 1 | O4: 官方情景展示时间表：09:00；地点：迎宾门外广场；常规节目，官方未公布逐日场次，按工作簿规则不建14表场次。介绍见 src_000003。
A5: prg_000002 | B5: pl_000001 | D5: 包公巡视汴河漕运 | E5: performance | F5: 以北宋汴河漕运为背景的水上巡游演出。 | H5: 待核实 | I5: src_000002 | J5: candidate | M5: 成员1 | N5: 1 | O5: 时间：09:20；地点：虹桥两侧水面；常规节目，未公布逐日场次。介绍见 src_000003。
A6: prg_000003 | B6: pl_000001 | D6: 宋廷梦乐 | E6: performance | F6: 以宋词为引子，融合箫、笛、埙、古琴、古筝、编磬等宋朝主流乐器的皇家乐典。 | H6: 待核实 | I6: src_000002 | J6: candidate | M6: 成员1 | N6: 1 | O6: 时间：10:20,11:40,14:50,16:35；地点：宣德殿二层；常规节目，未公布逐日场次。介绍见 src_000003。
A7: prg_000004 | B7: pl_000001 | D7: 王员外招婿 | E7: performance | F7: 王员外搭绣楼为女儿招亲的互动演出。 | H7: 待核实 | I7: src_000002 | J7: candidate | M7: 成员1 | N7: 1 | O7: 时间：11:45,15:40,16:50；地点：王员外家；常规节目，未公布逐日场次。介绍见 src_000003。
A8: prg_000005 | B8: pl_000001 | D8: 岳飞枪挑小梁王 | E8: performance | F8: 以岳飞武举科考为背景的实景演出。 | H8: 待核实 | I8: src_000002 | J8: candidate | M8: 成员1 | N8: 1 | O8: 时间：10:50,16:10；地点：大宋·校场；常规节目，未公布逐日场次。介绍见 src_000003。
A9: prg_000006 | B9: pl_000001 | D9: 大宋·东京保卫战 | E9: performance | F9: 运用火药、威亚、攻城、跳河等电影特效的战争实景演出。 | H9: 待核实 | I9: src_000002 | J9: candidate | M9: 成员1 | N9: 1 | O9: 时间：10:00,17:20；地点：九龙桥西南水面；常规节目，未公布逐日场次。介绍见 src_000003。
A10: prg_000007 | B10: pl_000001 | D10: 清明上河园大巡游 | E10: performance | F10: 园区大型巡游演出。 | H10: 待核实 | I10: src_000002 | J10: candidate | M10: 成员1 | N10: 1 | O10: 时间：14:00；路线：虹桥南广场至双宣殿；常规节目，未公布逐日场次。
A11: prg_000008 | B11: pl_000001 | D11: 打铁花之盛世大宋 | E11: performance | F11: 国家级非物质文化遗产打铁花表演。 | H11: 待核实 | I11: src_000002 | J11: candidate | M11: 成员1 | N11: 1 | O11: 时间：21:00；地点：九龙桥西南水面；常规节目，未公布逐日场次。介绍见 src_000003。
A12: prg_000009 | B12: pl_000001 | D12: 大宋·东京梦华 | E12: performance | F12: 大型水上实景演出，全剧70分钟，700多名演员参与，以八阕宋词和《清明上河图》串联。 | H12: 《大宋·东京梦华》演出票（是否含景区门票待核实） | I12: src_000009 | J12: candidate | M12: 成员1 | N12: 1 | O12: 官方时间表标注“以景区公示为准”，未给固定时间；地点：景龙湖水面；未公布逐日场次，不建14表场次。介绍来源 src_000009；时间表来源 src_000002。
A13: prg_000010 | B13: pl_000002 | D13: 打铁花 | E13: performance | F13: 流传于豫晋地区的国家级非物质文化遗产，起源于北宋；艺人将生铁熔化成约1600℃的铁水，击打后形成火树银花。 | H13: 待核实 | I13: src_000012 | J13: candidate | M13: 成员1 | N13: 1 | O13: 官方节目单（水浒区·城寨沙场）：19:30/21:00/22:15（待定），30分钟，需预约；常规时刻，不是逐日场次。介绍来源 src_000012；节目单来源 src_000014。
A14: prg_000011 | B14: pl_000002 | D14: 三打祝家庄 | E14: performance | F14: 大型水浒实景剧，地点在城寨沙场，演出时长约30分钟，融合马战、步兵战、攻城战、全景式爆破、飞火流星、云梯炮战等实景特效，上百名演员、十几匹马参与。 | H14: 待核实 | I14: src_000012 | J14: candidate | M14: 成员1 | N14: 1 | O14: 官方节目单（水浒区·城寨沙场）：11:00/14:00（待定）/17:00，30分钟，需预约；常规时刻，不是逐日场次。介绍来源 src_000012；节目单来源 src_000014。
A15: prg_000012 | B15: pl_000002 | D15: 王婆说媒 | E15: performance | F15: 无剧本、无托儿的沉浸互动相亲类演出，由王婆扮演者赵梅主持，现场随机招募单身男女嘉宾。 | H15: 待核实 | I15: src_000012 | J15: candidate | M15: 成员1 | N15: 1 | O15: 官方节目单：水浒区页面显示“今日停演”；仙侠奇境区·魔力广场 16:30，90分钟。常规时刻，不是逐日场次。介绍来源 src_000012；节目单来源 src_000014。
... A19: prg_000016 | B19: pl_000002 | D19: 室内三大剧场 | E19: performance | F19: 戏剧剧场演绎《贵妃醉酒》《坐宫》等；T台剧场呈现《抽象行走》《量子纠缠》《花语走秀》等；粮仓剧场上演《岳飞的呐喊》和沙画。 | H19: 待核实 | I19: src_000012 | J19: candidate | M19: 成员1 | N19: 1 | O19: 官方节目单按戏曲剧场/舞秀剧场/音乐广场分列；代表场次：剪韵华裳15:35/16:35/17:30/20:00/20:50/21:25；花语走秀18:30/19:15；量子纠缠09:45/10:45/11:50/12:50/14:10/16:00/17:00。常规时刻，不是逐日场次。介绍来源 src_000012；节目单来源 src_000014。
A20: prg_000017 | B20: pl_000002 | D20: 祭火迎神 | E20: performance | H20: 待核实 | I20: src_000010 | J20: candidate | M20: 成员1 | N20: 1 | O20: 官方节目单（水浒区·武侠广场）：19:30（待定）/21:00（待定）/22:15（待定），10分钟；常规时刻，不是逐日场次。介绍来源 src_000010；节目单来源 src_000014。
A21: prg_000018 | B21: pl_000002 | D21: 林冲战杨志 | E21: performance | H21: 待核实 | I21: src_000010 | J21: candidate | M21: 成员1 | N21: 1 | O21: 官方节目单（水浒区·水浒街）：10:15，10分钟；常规时刻，不是逐日场次。介绍来源 src_000010；节目单来源 src_000014。
A22: prg_000019 | B22: pl_000002 | D22: 二娘的秀 | E22: performance | H22: 待核实 | I22: src_000010 | J22: candidate | M22: 成员1 | N22: 1 | O22: 官方节目单（水浒区·武侠广场）：17:30，90分钟；常规时刻，不是逐日场次。介绍来源 src_000010；节目单来源 src_000014。
A23: prg_000020 | B23: pl_000003 | D23: 开衙迎宾 | E23: performance | F23: 开封府开衙迎宾仪式。 | H23: 日间票 | I23: src_000016 | J23: candidate | M23: 成员1 | N23: 1 | O23: 官方节目单：09:00；地点：府门广场；常规时刻，不是逐日场次。节目单来源 src_000016。
A24: prg_000021 | B24: pl_000003 | D24: 包公断案（铡美案） | E24: performance | F24: 包公断案实景演出《铡美案》。 | H24: 日间票 | I24: src_000016 | J24: candidate | M24: 成员1 | N24: 1 | O24: 官方节目单：09:30；地点：大堂；常规时刻，不是逐日场次。节目单来源 src_000016。
A25: prg_000022 | B25: pl_000003 | D25: 《闸口盘车案》影院版 | E25: performance | F25: 全息影院版《闸口盘车案》。 | H25: 日间票 | I25: src_000016 | J25: candidate | M25: 成员1 | N25: 1 | O25: 官方节目单：09:40/11:55/16:30；地点：全息剧场；常规时刻，不是逐日场次。节目单来源 src_000016。 需提前到全息剧场门口预约取票。
A26: prg_000023 | B26: pl_000003 | D26: 太子迎驾 | E26: performance | F26: 太子迎驾情景演出。 | H26: 日间票 | I26: src_000016 | J26: candidate | M26: 成员1 | N26: 1 | O26: 官方节目单：10:00；地点：太子读书台；常规时刻，不是逐日场次。节目单来源 src_000016。
A27: prg_000024 | B27: pl_000003 | D27: 榜前捉婿 | E27: performance | F27: 明礼院榜前捉婿互动演出。 | H27: 日间票 | I27: src_000016 | J27: candidate | M27: 成员1 | N27: 1 | O27: 官方节目单：10:30/15:30；地点：明礼院；常规时刻，不是逐日场次。节目单来源 src_000016。
A28: prg_000025 | B28: pl_000003 | D28: 《闸口盘车案》剧场版 | E28: performance | F28: 全息剧场版《闸口盘车案》。 | H28: 日间票 | I28: src_000016 | J28: candidate | M28: 成员1 | N28: 1 | O28: 官方节目单：11:00/14:30/17:30；地点：全息剧场；常规时刻，不是逐日场次。节目单来源 src_000016。
A29: prg_000026 | B29: pl_000003 | D29: 太极功夫 | E29: performance | F29: 天庆观太极功夫表演。 | H29: 日间票 | I29: src_000016 | J29: candidate | M29: 成员1 | N29: 1 | O29: 官方节目单：11:00/15:00；地点：天庆观；常规时刻，不是逐日场次。节目单来源 src_000016。
A30: prg_000027 | B30: pl_000003 | D30: 演武迎宾 | E30: performance | F30: 英武楼演武迎宾表演。 | H30: 日间票 | I30: src_000016 | J30: candidate | M30: 成员1 | N30: 1 | O30: 官方节目单：11:35/16:40；地点：英武楼；常规时刻，不是逐日场次。节目单来源 src_000016。
A31: prg_000028 | B31: pl_000003 | D31: 包公巡衙之巧遇苏轼 | E31: performance | F31: 包公巡衙途中巧遇苏轼的情景演出。 | H31: 日间票 | I31: src_000016 | J31: candidate | M31: 成员1 | N31: 1 | O31: 官方节目单：12:30/17:00；地点：街道司；常规时刻，不是逐日场次。节目单来源 src_000016。
A32: prg_000029 | B32: pl_000003 | D32: 包公断案（铡赵王） | E32: performance | F32: 包公断案实景演出《铡赵王》。 | H32: 日间票 | I32: src_000016 | J32: candidate | M32: 成员1 | N32: 1 | O32: 官方节目单：14:00；地点：大堂；常规时刻，不是逐日场次。节目单来源 src_000016。
A33: prg_000030 | B33: pl_000003 | D33: 水月云天舞+音乐喷泉秀 | E33: performance | F33: 明镜湖水月云天舞与音乐喷泉秀。 | H33: 夜游票《南衙千秋月》 | I33: src_000016 | J33: candidate | M33: 成员1 | N33: 1 | O33: 官方节目单：18:00；地点：明镜湖；常规时刻，不是逐日场次。节目单来源 src_000016。
A34: prg_000031 | B34: pl_000003 | D34: 一座府·天下首府 | E34: performance | F34: 大堂夜间实景演出《一座府·天下首府》。 | H34: 夜游票《南衙千秋月》 | I34: src_000016 | J34: candidate | M34: 成员1 | N34: 1 | O34: 官方节目单：19:20；地点：大堂；常规时刻，不是逐日场次。节目单来源 src_000016。
A35: prg_000032 | B35: pl_000004 | D35: 太祖大典 | E35: performance | H35: 日间票 | I35: src_000019 | J35: candidate | M35: 成员1 | N35: 1 | O35: 官方节目单：16:30；地点：龙亭大殿；常规时刻，不是逐日场次。节目单来源 src_000025。
A36: prg_000033 | B36: pl_000004 | D36: 皇城司 | E36: performance | H36: 日间票 | I36: src_000019 | J36: candidate | M36: 成员1 | N36: 1 | O36: 官方节目单：11:30/17:05；地点：宣和殿；常规时刻，不是逐日场次。节目单来源 src_000025。
A37: prg_000034 | B37: pl_000004 | D37: 江山乐舞 | E37: performance | H37: 日间票 | I37: src_000019 | J37: candidate | M37: 成员1 | N37: 1 | O37: 官方节目单：14:45；地点：皇冠舞台；常规时刻，不是逐日场次。节目单来源 src_000025。
A38: prg_000035 | B38: pl_000004 | D38: 大宋科举 | E38: performance | H38: 待核实 | I38: src_000019 | J38: candidate | M38: 成员1 | N38: 1 | O38: 官方节目单未列，可能已调整/停演；待核实。
A39: prg_000036 | B39: pl_000004 | D39: 宫廷迎宾 | E39: performance | H39: 待核实 | I39: src_000019 | J39: candidate | M39: 成员1 | N39: 1 | O39: 官方节目单未列；可能与“大宋金戈·迎宾盛礼”对应，待核实。
A40: prg_000037 | B40: pl_000004 | D40: 大宋金戈·迎宾盛礼 | E40: performance | H40: 日间票 | I40: src_000025 | J40: candidate | M40: 成员1 | N40: 1 | O40: 白天：09:30；地点：午门广场。 常规时刻，不是逐日场次。节目单来源 src_000025。
A41: prg_000038 | B41: pl_000004 | D41: 金甲舞蹈 | E41: performance | H41: 日间票 | I41: src_000025 | J41: candidate | M41: 成员1 | N41: 1 | O41: 白天：09:40（御道）、11:50（皇冠舞台）。 常规时刻，不是逐日场次。节目单来源 src_000025。
A42: prg_000039 | B42: pl_000004 | D42: 金甲巡游 | E42: performance | H42: 日间票 | I42: src_000025 | J42: candidate | M42: 成员1 | N42: 1 | O42: 白天：09:40/10:30/11:20/14:30/17:10；地点：御道/园内。 常规时刻，不是逐日场次。节目单来源 src_000025。
A43: prg_000040 | B43: pl_000004 | D43: 菊风乐舞 | E43: performance | H43: 日间票 | I43: src_000025 | J43: candidate | M43: 成员1 | N43: 1 | O43: 白天：09:40（龙亭大殿）、11:40（皇冠舞台）。 常规时刻，不是逐日场次。节目单来源 src_000025。
...

Sheet 14_show_sessions
A1: 演出场次 show_sessions
A2: 仅收集候选与核实数据；不得把格式正确误判为事实真实。导入前请运行校验脚本。
A3: session_id | B3: program_id | C3: park_place_id | D3: stage_place_id | E3: session_date | F3: starts_at | G3: ends_at | H3: timezone | I3: session_status | J3: ticket_scope | K3: source_id | L3: checked_at | M3: valid_until | N3: validation_status | O3: reviewer | P3: version | Q3: notes

Sheet 15_food_items
A1: 美食菜品表 food_items
A2: 仅收集候选与核实数据；不得把格式正确误判为事实真实。导入前请运行校验脚本。
A3: food_id | B3: name | C3: aliases | D3: category | E3: flavor_tags | F3: dietary_tags | G3: intro | H3: intro_source_id | I3: validation_status | J3: reviewer | K3: version | L3: notes
A4: food_000001 | B4: 灌汤包 | C4: 开封灌汤包；小笼灌汤包；灌汤包子 | D4: 面点小吃 | G4: 携程餐厅页面将灌汤包列为第一楼总店推荐菜。此条用于建立菜品候选，不代表所有商家均供应或当前仍在售。 | H4: src_000064 | I4: candidate | K4: 1 | L4: 后续核实具体商家、分店和实时菜单；不同店铺馅料及配方可能不同。
A5: food_000002 | B5: 鲤鱼焙面 | C5: 糖醋鲤鱼焙面；糖醋软熘鲤鱼焙面 | D5: 传统豫菜/鱼类名菜 | E5: 软嫩鲜香；焙面酥脆；糖醋风味 | F5: 含鱼类；含小麦（焙面，具体配方待核实） | G5: 开封市鼓楼区政府的美食介绍称，鲤鱼焙面由糖醋熘鱼与焙龙须面配制，介绍了鱼肉软嫩鲜香、焙面蓬松酥脆等特点。 | H5: src_000060 | I5: candidate | K5: 1 | L5: 简介来自地方政府文化介绍；具体门店供应及配料需单独核实。
A6: food_000003 | B6: 桶子鸡 | C6: 开封桶子鸡；桶子鸡（部分平台写作筒子鸡） | D6: 传统熟食/地方名菜 | E6: 咸香；嫩脆；肥而不腻 | F6: 含鸡肉（具体配方待核实） | G6: 商务部老字号数字博物馆的福兴斋品牌页面介绍桶子鸡产品及其传统卤制工艺，并描述其皮脆肉嫩、肥而不腻等特点。 | H6: src_000062 | I6: candidate | K6: 1 | L6: 品牌资料支持菜品候选与文化介绍，不证明其他商家或分店当前供应。
A7: food_000004 | B7: 炒凉粉 | C7: 汴梁炒凉粉；汴京炒凉粉；铁板炒凉粉 | D7: 地方小吃 | E7: 外焦里嫩；豆豉酱香 | G7: 开封市鼓楼区政府的美食介绍将炒凉粉列为地方传统小吃，并介绍其以红薯凉粉和调料炒制，口感外焦里嫩。 | H7: src_000060 | I7: candidate | K7: 1 | L7: 平台菜单中可能出现铁板凉粉等近似名称，是否属于同一具体菜品仍需人工确认。
A8: food_000005 | B8: 杏仁茶 | C8: 汴京杏仁茶；八宝杏仁茶 | D8: 传统饮品/小吃 | F8: 可能含坚果/种子类配料；具体过敏原以商家配方为准 | G8: 携程餐厅页面将杏仁茶列为第一楼总店推荐菜；不同店铺的配料、名称和做法可能存在差异。 | H8: src_000064 | I8: candidate | K8: 1 | L8: 不得仅凭菜名断言完整配方或过敏原；后续按具体商家菜单核对。
A9: food_000006 | B9: 花生糕 | C9: 兴盛德传统花生糕 | D9: 传统糕点 | F9: 含花生（名称所示） | G9: 携程页面将兴盛德传统花生糕列为兴盛德花生老店的推荐商品之一。 | H9: src_000071 | I9: candidate | K9: 1 | L9: 商品配方、包装规格和当前库存需另行核实；花生为需关注的过敏原。
A10: food_000007 | B10: 羊肉炕馍 | C10: 炕馍 | D10: 面食小吃 | F10: 含羊肉（名称所示；其他配料待核实） | G10: 携程楼中楼酒店（汴梁小宋城店）页面将羊肉炕馍列为推荐菜。 | H10: src_000067 | I10: candidate | K10: 1 | L10: 菜品配方、实际供应和价格需按具体商家核实。
A11: food_000008 | B11: 锅贴 | C11: 开封锅贴 | D11: 面点小吃 | G11: 携程稻香居锅贴（宋都御街店）页面将锅贴列为推荐菜；高德榜单也将邢家锅贴老店列为锅贴候选商家。 | H11: src_000070 | I11: candidate | K11: 1 | L11: 不同店铺馅料和做法不同，暂不标注素食或具体过敏原。
A12: food_000009 | B12: 三狠汤 | C12: 开封三狠汤；三狠汤（酸辣咸） | D12: 汤类/地方小吃 | E12: 酸；辣；咸（平台/菜单名称描述） | G12: 携程第一楼总店及中兴楼页面均将三狠汤列入推荐菜。 | H12: src_000064 | I12: candidate | K12: 1 | L12: 具体配方、辣度和食材需按商家核实。
A13: food_000010 | B13: 黄焖鱼 | C13: 汴梁黄焖鱼；开封黄焖鱼 | D13: 鱼类菜肴 | F13: 含鱼类（名称所示；具体鱼种待核实） | G13: 携程黄家老店（宋城路店）页面将汴梁黄焖鱼列为推荐菜。 | H13: src_000065 | I13: candidate | K13: 1 | L13: 不同店铺鱼种、做法和配料可能不同；正式推荐前核实菜单。
A14: food_000011 | B14: 朱仙镇豆干丝 | C14: 朱仙镇豆腐干丝；豆干丝 | D14: 豆制品/小吃 | F14: 含大豆（菜品名称所示；调味料待核实） | G14: 携程黄家老店（宋城路店）页面将朱仙镇豆干丝列为推荐菜。 | H14: src_000065 | I14: candidate | K14: 1 | L14: 不同商家的产品和调味配方可能不同。
A15: food_000012 | B15: 炸八块 | C15: 汴梁炸八块 | D15: 传统豫菜 | G15: 携程第一楼总店及梅利汴京烤鸭店页面均将炸八块/汴梁炸八块列为推荐菜。 | H15: src_000064 | I15: candidate | K15: 1 | L15: 与菜单中出现的“炸八件”分开建项，避免未经证实地合并名称。
A16: food_000013 | B16: 炸八件 | D16: 传统豫菜 | G16: 携程中兴楼（汴京路店）页面将炸八件列为推荐菜。 | H16: src_000068 | I16: candidate | K16: 1 | L16: 与“炸八块”分开建项；二者是否为同一菜品/地方叫法待核实。
A17: food_000014 | B17: 炒红薯泥 | C17: 红薯泥；明炉灼红薯泥（菜单名称近似，待核实） | D17: 地方菜/小吃 | G17: 携程稻香居锅贴页面将炒红薯泥列为推荐菜，楼中楼酒店页面也列有红薯泥。 | H17: src_000070 | I17: candidate | K17: 1 | L17: 近似菜名是否属于同一做法待核实；此条先作为候选项。
A18: food_000015 | B18: 胡辣汤 | C18: 清真胡辣汤 | D18: 汤食/早餐小吃 | G18: 携程李小记羊肉胡辣汤（清真店）页面将清真胡辣汤列为推荐菜。 | H18: src_000072 | I18: candidate | K18: 1 | L18: 不同店铺的配方可能不同，不据此推断具体食材。
A19: food_000016 | B19: 羊双肠 | D19: 汤食/早餐小吃 | G19: 携程开封美食列表列出西门郑羊双肠（大梁路店），并将其描述为本地早餐类候选。 | H19: src_000073 | I19: candidate | K19: 1 | L19: “羊双肠”的具体构成和配料未从该列表充分确认，正式介绍前需补充可靠菜品资料。
A20: food_000017 | B20: 五香豆沫 | C20: 豆沫 | D20: 汤食/早餐小吃 | G20: 携程开封美食列表列有李记五香豆沫，可作为开封早餐小吃候选。 | H20: src_000073 | I20: candidate | K20: 1 | L20: 具体原料、是否含坚果/芝麻或动物性成分均待商家菜单核实。
A21: food_000018 | B21: 驴肉汤 | C21: 驴肉汤（餐馆菜品候选） | D21: 汤食/早餐小吃 | F21: 含驴肉（名称所示；其他配料待核实） | G21: 携程开封美食列表列出化三驴肉汤馆（总店），页面描述其驴肉汤为候选特色菜。 | H21: src_000073 | I21: candidate | K21: 1 | L21: 具体供应、配方和营业信息需按商家核实。
A22: food_000019 | B22: 麻辣花生 | C22: 兴盛德麻辣花生 | D22: 零食/坚果 | E22: 麻辣；焦香酥脆（平台榜单描述） | F22: 含花生（名称所示） | G22: 高德开封美食榜和携程兴盛德花生老店页面均提到麻辣花生/兴盛德花生商品。 | H22: src_000071 | I22: candidate | K22: 1 | L22: 配料、辣度和包装商品当前库存需核实；花生为需关注的过敏原。
A23: food_000020 | B23: 汴京果木烤鸭 | C23: 果木烤鸭（梅利店菜单名称） | D23: 烤制菜肴 | F23: 含鸭肉（名称所示；具体配方待核实） | G23: 携程梅利汴京烤鸭（东司门店）页面将汴京果木烤鸭列为推荐菜。 | H23: src_000069 | I23: candidate | K23: 1 | L23: 此名称来自该店平台菜单，不代表所有开封餐馆均供应。
A24: food_000021 | B24: 四味菜 | C24: 开封四味菜 | D24: 地方菜/烩菜 | G24: 携程餐厅详情页将李记四味菜馆（书店街店）的特色菜列为“四味烩菜”；本项目暂将“四味菜”作为候选标准名称，名称对应关系仍需人工确认。 | H24: src_000085 | I24: candidate | K24: 2 | L24: 来源菜单使用“四味烩菜”而非完全相同的标准名称“四味菜”；暂作为候选，正式推荐前需核对命名和具体做法。
A25: food_000022 | B25: 羊肉胡辣汤 | C25: 传统羊肉胡辣汤 | D25: 汤食/早餐小吃 | F25: 含羊肉（名称所示；其他配料待核实） | G25: 携程李小记羊肉胡辣汤（清真店）页面将传统羊肉胡辣汤列为推荐菜。 | H25: src_000072 | I25: candidate | K25: 1 | L25: 具体配方、供应状态和过敏原信息需按商家核实。
A26: food_000023 | B26: 玉米糁 | D26: 粥/早餐 | G26: 携程李小记羊肉胡辣汤（清真店）页面将玉米糁列为推荐菜。 | H26: src_000072 | I26: candidate | K26: 1 | L26: 具体制作方法和当前供应需按商家核实。
A27: food_000024 | B27: 鸡蛋布袋 | C27: 鸡蛋袋（菜单近似名称，待核实） | D27: 面点/早餐小吃 | F27: 可能含鸡蛋及面制品；实际配方待商家核实 | G27: 携程李小记羊肉胡辣汤（清真店）页面列有鸡蛋布袋和鸡蛋袋等近似名称。 | H27: src_000072 | I27: candidate | K27: 1 | L27: “鸡蛋布袋”与“鸡蛋袋”是否为同一菜品待核实，暂保留候选关系，不标已核实。
A28: food_000025 | B28: 宫廷豌豆糕 | C28: 豌豆糕（近似名称，待核实） | D28: 传统糕点 | G28: 携程第一楼总店页面将宫廷豌豆糕列为推荐菜。 | H28: src_000064 | I28: candidate | K28: 1 | L28: 与其他商家菜单中的“桂花豌豆糕”分开核对，暂不假定配方和名称完全相同。
A29: food_000026 | B29: 开封传统米线 | C29: 米线（平台榜单描述，待核实） | D29: 主食/小吃 | E29: 香浓入味（平台榜单描述） | G29: 高德开封美食榜将三胜街田庆辉田记米线列为候选店铺，并描述其米线搭配豆皮、海带、鹌鹑蛋、咖喱粉和麻油；具体配方仍需商家确认。 | H29: src_000081 | I29: candidate | K29: 1 | L29: 描述来自地图平台榜单而非商家官方菜单；配料和当前供应需复核。

Sheet 16_food_vendors
A1: 商家表 food_vendors
A2: 仅收集候选与核实数据；不得把格式正确误判为事实真实。导入前请运行校验脚本。
A3: vendor_id | B3: place_id | C3: name | D3: aliases | E3: address | F3: lng | G3: lat | H3: crs | I3: external_poi_id | J3: business_hours | K3: price_band | L3: dine_in | M3: takeaway | N3: inside_scenic | O3: source_id | P3: validation_status | Q3: verified_at | R3: reviewer | S3: version | T3: notes
A4: ven_000001 | C4: 第一楼·中华老字号（寺后街总店） | D4: 第一楼；第一楼灌汤包总店 | E4: 河南省开封市鼓楼区寺后街8号 | F4: 114.35192 | G4: 34.794059 | H4: GCJ-02 | I4: B017A00HWY | J4: 10:30-14:00；17:30-21:00 | K4: 60-70元/人 | L4: true | M4: unknown | N4: unknown | O4: src_000106 | P4: candidate | S4: 3 | T4: 地址、营业时间和人均消费来自携程页面；非商家实时官方确认，推荐前复核。 营业时间为平台页面展示值，正式推荐前需复核。 平台页面显示人均约64元，仅为参考消费，不是单道菜价格。 第三轮核查（2026-10-22）：高德地点页直接支持寺后街8号、坐标34.794059/114.351924及POI B017A00HWY；携程另有可访问餐厅详情页支持营业时段。高德评价较早，当前营业状态仍需电话确认。
A5: ven_000002 | C5: 黄家老店（宋城路店） | D5: 黄家老店宋城路店 | E5: 河南省开封市宋城路凤凰城1号楼 | F5: 114.32478 | G5: 34.785167 | H5: GCJ-02 | I5: B017A00L40 | J5: 10:00-21:30 | K5: 50-60元/人 | L5: true | M5: unknown | N5: unknown | O5: src_000107 | P5: candidate | S5: 3 | T5: 营业时间、价格和推荐菜来自携程页面；当前状态需再次确认。 营业时间为平台页面展示值，正式推荐前需复核。 平台页面显示人均约53元，仅为参考消费，不是单道菜价格。 第三轮核查（2026-10-22）：高德地点页直接支持宋城路凤凰城1号楼地址、坐标34.785167/114.324778及POI B017A00L40。可见评价较早，当前营业状态仍需确认。
A6: ven_000003 | C6: 黄家老店（晋安路店） | D6: 黄家老店晋安路店 | E6: 河南省开封市晋安路中段宏泰怡园1号楼底商（武夷夜市南头） | J6: 10:30-21:00 | K6: 50-60元/人 | L6: true | M6: unknown | N6: unknown | O6: src_000112 | P6: candidate | S6: 3 | T6: 营业时间、价格和推荐菜来自携程页面；当前状态需再次确认。 营业时间为平台页面展示值，正式推荐前需复核。 平台页面显示人均约59元，仅为参考消费，不是单道菜价格。 第三轮核查（2026-10-22）：Trip.com页面再次列出晋安路中段宏泰怡园1号楼底商（武夷夜市南头）、10:30-21:00及电话0371-23858988；本轮未取得可靠坐标，未推算经纬度。
A7: ven_000004 | C7: 楼中楼酒店（汴梁小宋城店） | D7: 楼中楼酒店小宋城店 | E7: 河南省开封市大梁路汴梁小宋城小吃城一楼擂台东侧6号/7号附近 | J7: 10:00-14:00；17:00-21:00 | K7: 60-70元/人 | L7: true | M7: unknown | N7: unknown | O7: src_000067 | P7: candidate | S7: 2 | T7: 地址描述来自携程页面，门牌及当前营业信息仍需复核。 营业时间为平台页面展示值，正式推荐前需复核。 平台页面显示人均约61元，仅为参考消费，不是单道菜价格。
A8: ven_000005 | C8: 中兴楼（汴京路店） | D8: 中兴楼汴京路店 | E8: 河南省开封市顺河回族区汴京路43号（汴京公园旁西约30米） | F8: 114.37032 | G8: 34.793215 | H8: GCJ-02 | I8: B017A000DA | J8: 10:30-14:00；17:00-21:00 | K8: 70-80元/人 | L8: true | M8: unknown | N8: unknown | O8: src_000108 | P8: candidate | S8: 3 | T8: 地址、营业时间和人均消费来自携程页面；非商家实时官方确认。 营业时间为平台页面展示值，正式推荐前需复核。 平台页面显示人均约77元，仅为参考消费，不是单道菜价格。 第三轮核查（2026-10-22）：高德地点页直接支持汴京路43号、坐标34.793215/114.370321及POI B017A000DA；携程页面支持营业时段10:30-14:00、17:00-21:00。高德评价较早，营业状态仍需电话确认。
A9: ven_000006 | C9: 梅利汴京烤鸭·开封豫菜地标店（东司门店） | D9: 梅利汴京烤鸭东司门店 | E9: 河南省开封市解放路与曹门大街交叉口东约60米路南 | J9: 10:00-21:00 | K9: 50-60元/人 | L9: true | M9: unknown | N9: unknown | O9: src_000069 | P9: candidate | S9: 3 | T9: 地址、营业时间和人均消费来自携程页面；当前营业与菜单需复核。 营业时间为平台页面展示值，正式推荐前需复核。 平台页面显示人均约56元，仅为参考消费，不是单道菜价格。 第三轮核查（2026-10-22）：携程支持本记录“东司门店”位于解放路与曹门大街交叉口东约60米路南，营业时段10:00-21:00。高德检索到的“梅利烤鸭店（东大街店）”在财政厅东街29号附1号，属于名称不同的另一分店，不得将其地址/坐标填入本记录；本轮仍未取得东司门店的可靠高德坐标。
A10: ven_000007 | C10: 稻香居锅贴（宋都御街店） | D10: 稻香居锅贴 | E10: 河南省开封市宋都御街73号 | F10: 114.35201 | G10: 34.800888 | H10: GCJ-02 | I10: B017A00K1Y | J10: 10:00-20:00 | K10: 40-50元/人 | L10: true | M10: unknown | N10: unknown | O10: src_000109 | P10: candidate | S10: 3 | T10: 地址、营业时间和人均消费来自携程页面；当前营业与菜单需复核。 营业时间为平台页面展示值，正式推荐前需复核。 平台页面显示人均约44元，仅为参考消费，不是单道菜价格。 第三轮核查（2026-10-22）：高德地点页直接支持宋都御街73号、坐标34.800888/114.352005及POI B017A00K1Y。可见评价较早，当前营业状态仍需复核。
A11: ven_000008 | C11: 兴盛德花生老店（中山路店） | D11: 兴盛德花生老店 | E11: 河南省开封市相国寺街道中山路北段84号 | J11: 08:00-21:00 | K11: 20-30元/人 | L11: unknown | M11: unknown | N11: unknown | O11: src_000071 | P11: candidate | S11: 2 | T11: 该页主要用于店铺/商品候选；商品零售形式、库存及当前营业需复核。 营业时间为平台页面展示值，正式推荐前需复核。 平台页面显示人均约29元，仅为参考消费，不是单道菜价格。
A12: ven_000009 | C12: 李小记羊肉胡辣汤（清真店） | D12: 李小记羊肉胡辣汤 | E12: 河南省开封市顺河回族区苹果园东路与苹果园中路交叉口往南约20米路东（高德POI地址描述为劳动路苹东社区，需确认同一入口） | F12: 114.38036 | G12: 34.807061 | H12: GCJ-02 | I12: B017A0NJMD | J12: 06:00-10:00 | K12: 0-10元/人 | L12: true | M12: unknown | N12: unknown | O12: src_000110 | P12: pending_review | S12: 3 | T12: 营业时间为早餐时段，来自携程页面；清真标识与菜品配方需以商家当前信息为准。 营业时间为平台页面展示值，正式推荐前需复核。 平台页面显示人均约7元，仅为参考消费，不是单道菜价格。 第三轮核查（2026-10-22）：携程与高德页面的电话均为13938618226，支持同一商家的可能性；携程给出苹果园东路/中路交叉口详细位置，高德给出劳动路苹东社区和坐标34.807061/114.380358。因地址表述不完全一致，保留坐标但标记待人工核对入口。
A13: ven_000010 | C13: 邢家锅贴老店（大梁门总店） | D13: 邢家锅贴大梁门总店 | E13: 河南省开封市龙亭区西门大街198号（大梁门东约50米路北） | F13: 114.33517 | G13: 34.801001 | H13: GCJ-02 | I13: B0FFG9U3L7 | L13: true | M13: unknown | N13: unknown | O13: src_000075 | P13: candidate | S13: 3 | T13: 地址/坐标来自高德地点页；平台列表价格为人均参考；营业时间待查。 初步核查：当前高德来源只支持门店名称、地址和坐标；原人均约58元未找到对应来源，已清空待核实。 第三轮核查（2026-10-22）：重新打开高德地点页，地址及坐标与现有记录一致（西门大街198号、大梁门东约50米路北；34.801001/114.335170；POI B0FFG9U3L7）。可见评价较早，当前营业状态仍需复核。
A14: ven_000011 | C14: 邢家锅贴老店（苹果园店） | D14: 邢家锅贴苹果园店 | E14: 河南省开封市顺河回族区东环北路40号 | F14: 114.37405 | G14: 34.807511 | H14: GCJ-02 | I14: B017A0NNWI | L14: unknown | M14: unknown | N14: unknown | O14: src_000076 | P14: pending_review | S14: 2 | T14: 高德页面提供地址与坐标，但未提供完整营业时间、价格和当前菜品信息；需进一步核实。 第三轮核查（2026-10-22）：重新打开高德地点页确认东环北路40号；现有坐标34.807511/114.374048来自此前记录，本轮页面渲染只显示地址、未重新展示坐标，因此坐标仍需在高德App地图针上人工复核。携程页面另显示10:00-14:00、17:00-21:00。
A15: ven_000012 | C15: 宋都禾源灌汤包子（鼎立店） | D15: 宋都禾源灌汤包子鼎立店 | E15: 河南省开封市龙亭区黄河路北段鼎立·国际城 | F15: 114.3224 | G15: 34.81801 | H15: GCJ-02 | I15: B0FFK26VO8 | L15: unknown | M15: unknown | N15: unknown | O15: src_000077 | P15: pending_review | S15: 2 | T15: 高德页面提供地址与坐标，营业时间、价格及当前供应菜品待核实。 第三轮核查（2026-10-22）：高德地点页支持黄河路北段鼎立·国际城、坐标34.818010/114.322401及POI B0FFK26VO8；未显示完整营业时段，且可见评价较早，需确认当前营业。
A16: ven_000013 | C16: 宋园灌汤小笼包子（集英街店） | D16: 宋园灌汤小笼包集英街店 | E16: 河南省开封市龙亭区汉兴路与集英街交叉口路西 | F16: 114.29026 | G16: 34.792195 | H16: GCJ-02 | I16: B0FFIIMUD7 | L16: unknown | M16: unknown | N16: unknown | O16: src_000078 | P16: candidate | S16: 2 | T16: 高德页面提供地址与坐标；高德2025美食榜将其列为热门店铺，但当前营业与菜单仍需核实。 第三轮核查（2026-10-22）：高德地点页支持汉兴路与集英街交叉口路西、坐标34.792195/114.290257及POI B0FFIIMUD7；公开评价较早，当前营业状态需复核。
A17: ven_000014 | C17: 闫记灌汤包 | E17: 河南省开封市龙亭区金耀路186-187号 | F17: 114.33394 | G17: 34.812002 | H17: GCJ-02 | I17: B0IBFS1EZM | L17: unknown | M17: unknown | N17: unknown | O17: src_000079 | P17: pending_review | S17: 2 | T17: 高德页面提供地址与坐标；营业时间、价格和当前菜单未显示，需核实。 第三轮核查（2026-10-22）：高德地点页支持金耀路186-187号、坐标34.812002/114.333943及POI B0IBFS1EZM；可见评价较早，当前营业状态需复核。
A18: ven_000015 | C18: 马豫兴桶子鸡（金玉斋牛肉万宝店） | D18: 马豫兴桶子鸡万宝店 | E18: 河南省开封市龙亭区大梁路省四队103队1-1-2号 | F18: 114.32437 | G18: 34.80186 | H18: GCJ-02 | I18: B0FFF5UIZH | L18: unknown | M18: unknown | N18: unknown | O18: src_000080 | P18: candidate | S18: 2 | T18: 高德页面提供地址与坐标；榜单将其列为桶子鸡候选商家，营业时间和当前商品需核实。 第三轮核查（2026-10-22）：高德地点页支持大梁路省四队103队1-1-2号、坐标34.801860/114.324365及POI B0FFF5UIZH；可见评价日期为2023年，当前营业状态需复核。
A19: ven_000016 | C19: 黄家老店（西司店） | D19: 黄家老店西司店 | E19: 河南省开封市鼓楼区西司门街16号 | J19: 10:30-21:00 | K19: 50-60元/人 | L19: unknown | M19: unknown | N19: unknown | O19: src_000113 | P19: pending_review | S19: 4 | T19: 携程列表显示店名、鼓楼广场附近位置和人均参考价；精确门牌、营业时间和当前菜单待核实。 初步核查：携程列表显示人均约55元、10:30营业；仅有开门时间，关门时间及精确门牌仍待核实。 地址重点核查（2026-10-22）：去哪儿页面列出西司门街16号；坐标未找到可靠的高德精确POI，暂留空。 第三轮核查（2026-10-22）：Trip.com与去哪儿均列西司门街16号、电话0371-25662988；Trip.com显示10:30-21:00。第三方POI镜像以同一电话列省府西街16号，地址文字存在差异；没有可靠坐标，先保留两平台一致的西司门街16号并待高德App核对。
A20: ven_000017 | C20: 张记逍遥胡辣汤（大坑沿街店） | D20: 张记逍遥胡辣汤 | E20: 河南省开封市鼓楼区西司门街道大坑沿街80号（省府前街与大坑沿街交叉口向北约150米路东） | J20: 06:30-12:00 | K20: 10-20元/人 | L20: unknown | M20: unknown | N20: unknown | O20: src_000089 | P20: pending_review | S20: 5 | T20: 携程列表支持店名及早餐类候选；具体门牌、完整营业时段及当前菜单待核实。 携程列表显示06:30营业，仅显示开门时间。 平台页面显示人均约11元/人，仅供消费预算参考，不是单道菜价格。 地址与营业时段核查（2026-10-22）：携程详情页列出大坑沿街80号及06:30-12:00；平台展示值，需商家确认。 第三轮核查（2026-10-22）：携程页面再次支持大坑沿街80号、06:30-12:00及电话13271147781，页面有2025-09-05用户评价；本轮未找到可确认该分店的高德精确坐标，不能从门牌地址推算坐标。
A21: ven_000018 | C21: 化三驴肉汤馆（总店） | D21: 化三驴肉汤 | E21: 河南省开封市龙亭区金耀路首座时代（园林小区大门对面；第三方目录另列金耀路59号，门牌待确认） | J21: 06:30-15:30 | K21: 30-40元/人 | L21: unknown | M21: unknown | N21: unknown | O21: src_000090 | P21: pending_review | S21: 5 | T21: 携程列表支持店名及驴肉汤候选；精确地址、完整营业时段和当前供应待核实。 携程列表显示06:30营业，仅显示开门时间。 平台页面显示人均约36元/人，仅供消费预算参考，不是单道菜价格。 地址交叉核查（2026-10-22）：携程页面支持“金耀路首座时代、园林小区大门对面”地标，查号吧列出金耀路59号及相对位置；门牌号来自第三方目录，需在高德/商家处复核。 第三轮核查（2026-10-22）：携程页面支持“金耀路首座时代（园林小区大门对面）”、06:30-15:30，页面电话为17303784449；查号吧另列金耀路59号和电话0371-28888886。两来源位置描述相容，但电话不同且精确门牌只由第三方目录提供，因此地址降为地标级描述，门牌及当前联系方式需确认。
A22: ven_000019 | C22: 西门郑羊双肠（大梁路店） | D22: 西门郑羊双肠 | E22: 河南省开封市龙亭区大梁路1号（梁园市场西门附近；Trip.com页面使用历史行政区称“金明区”） | J22: 06:30-14:00 | K22: 20-30元/人 | L22: unknown | M22: unknown | N22: unknown | O22: src_000111 | P22: pending_review | S22: 5 | T22: 携程列表支持店名及羊双肠早餐候选；精确门牌、营业时段和菜品构成待核实。 携程列表显示06:30营业，仅显示开门时间。 平台页面显示人均约23元/人，仅供消费预算参考，不是单道菜价格。 地址核查（2026-10-22）：Trip.com页面列出大梁路1号及06:30-14:00；未找到可靠坐标，坐标字段继续留空。 第三轮核查（2026-10-22）：携程页面显示大梁路1号（梁园市场西门附近）、06:30-14:00、电话13353811330；页面有2025-09至2025-11用户评价。未找到该分店的高德精确坐标，坐标不填猜测值。
A23: ven_000020 | C23: 李记五香豆沫 | D23: 李记豆沫 | E23: 河南省开封市鼓楼区张老五羊肉鲜汤北门东约250米（携程列表另写丁角街2号，门牌待核实） | F23: 114.33825 | G23: 34.794724 | H23: GCJ-02 | I23: B0FFFPFWQH | J23: 05:30开门（关门时间未显示） | K23: 0-10元/人 | L23: unknown | M23: unknown | N23: unknown | O23: src_000093 | P23: conflict | S23: 6 | T23: 携程列表支持店名和豆沫候选；精确地址、完整营业时段和配方待核实。 携程列表显示05:30营业，仅显示开门时间。 平台页面显示人均约9元/人，仅供消费预算参考，不是单道菜价格。 地址/坐标交叉核查（2026-10-22）：携程列表列丁角街2号；高德页面提供相邻地标及坐标（GCJ-02，来源src_000093）。建议打开高德地图复核具体门牌。 二次核查（2026-10-22）：携程列表写“丁角街2号”，高德地点页只给附近地标和坐标34.794724,114.338246；该坐标与高德“西司广场夜市”（丁角街83号，坐标34.794594,114.338268，来源src_000105）约相距14-15米。地址门牌与POI坐标是否对应尚未确认，暂不把此坐标视为已核实的商家精确位置。 第三轮核查（2026-10-22）：高德直接POI支持附近地标与坐标34.794724/114.338246；携程列表写丁角街2号，但该坐标与高德西司广场夜市（丁角街83号，34.794594/114.338268）约相距14-15米。未能证明门牌与坐标完全对应，地址改为地标描述并标记conflict，导航前需在高德App核对地图针。
A24: ven_000021 | C24: 宋园灌汤小笼包（黄河路店） | D24: 宋园灌汤小笼包央视报道品牌黄河路店 | E24: 河南省开封市龙亭区黄河大街北段81号阳光新天地小区1号楼临街房 | J24: 11:30-14:00；17:30-21:00 | K24: 50-70元/人 | L24: unknown | M24: unknown | N24: unknown | O24: src_000095 | P24: pending_review | S24: 6 | T24: 携程列表显示店名、龙亭区位置和人均参考价；精确门牌、完整营业时段和当前菜单待核实。 携程列表显示11:30营业，仅显示开门时间。 平台页面显示人均约60元/人，仅供消费预算参考，不是单道菜价格。 地址核查（2026-10-22）：Trip.com详情页列出黄河大街北段81号及完整营业时段；抖音评论仅提供黄河大街北段的宽泛线索，不作为精确地址证据。 二次核查（2026-10-22）：Trip.com另一可见版本明确列“黄河大街北段81号、阳光新天地小区1号楼临街房”；携程详情页显示“黄河大街星光天地对面”。两者为详细地址与地标描述，基本相容，但尚未找到该分店的高德精确POI坐标，仍需人工复核门牌/入口。 第三轮核查（2026-10-22）：Trip.com页面支持黄河大街北段81号、阳光新天地1号楼临街房、11:30-14:00及17:30-21:00；页面可见2026-09-29用户点评。尚未找到能独立确认该分店坐标的高德POI，地址可作候选但地图针仍待核。
A25: ven_000022 | C25: 宋风雅宴·宋文化餐厅（双龙巷店） | D25: 宋风雅宴（双龙巷店）；宋风雅宴·宋文化地标餐厅（双龙巷店） | E25: 河南省开封市顺河回族区双龙巷历史文化区A7号院（宋风雅宴/杜孟模博物馆内） | F25: 114.36225 | G25: 34.801763 | H25: GCJ-02 | I25: B0JKPHTQWF | J25: 11:00-14:00；17:00-21:00 | K25: 70-90元/人 | L25: unknown | M25: unknown | N25: unknown | O25: src_000083 | P25: pending_review | S25: 3 | T25: 地址、坐标和电话来自高德地点页src_000083；营业时段11:00-14:00、17:00-21:00及人均约80元来自Trip.com页面src_000086。两个来源均为平台公开信息，非商家实时确认；正式推荐前复核。 第三轮核查（2026-10-22）：高德地点页支持双龙巷历史文化区A7号院、坐标34.801763/114.362246及POI B0JKPHTQWF；可见评价为2024年，当前营业状态仍需确认。
A26: ven_000023 | C26: 李记四味菜馆（书店街店） | D26: 李记四味菜馆 | E26: 河南省开封市龙亭区北书店街59号 | F26: 114.35623 | G26: 34.79904 | H26: GCJ-02 | I26: B017A0N74G | J26: 06:30-13:30 | K26: 10-20元/人 | L26: unknown | M26: unknown | N26: unknown | O26: src_000084 | P26: pending_review | S26: 3 | T26: 地址、坐标和电话来自高德地点页src_000084；携程餐厅详情页src_000085显示营业时间06:30-13:30、人均约19元，特色菜含“四味烩菜”。平台信息仍需正式推荐前复核。 第三轮核查（2026-10-22）：高德地点页支持北书店街59号、坐标34.799040/114.356232及POI B017A0N74G；携程页面有2026-09-29近期评价并列出四味烩菜等菜品。仍需确认当天实际供应及营业时段。
A27: ven_000024 | C27: 宋都禾源·灌汤包子（汉兴路直营店） | D27: 宋都禾源灌汤包汉兴路店 | E27: 河南省开封市龙亭区黄河大街东段与汉兴路交叉口东北角 | J27: 10:00-14:30；17:00-21:30 | K27: 50-60元/人 | L27: unknown | M27: unknown | N27: unknown | O27: src_000096 | P27: pending_review | S27: 5 | T27: 携程附近列表显示店名及人均参考价；只显示约10:00开门提示，完整营业时间和精确地址待核实。 携程附近美食页显示10:00营业，仅显示开门时间。 平台页面显示人均约54元/人，仅供消费预算参考，不是单道菜价格。 地址核查（2026-10-22）：携程详情页提供路口方位及营业时段；未提供精确门牌/坐标，正式推荐前复核。 第三轮核查（2026-10-22）：携程页面支持黄河大街东段与汉兴路交叉口东北角及10:00-14:30、17:00-21:30；本轮业务搜索还出现汉兴路16号院付2的“禾源/禾源汤包”地点线索，但无法确认是同一分店，因此不合并地址、不填坐标。
A28: ven_000025 | C28: 贪烤 | E28: 河南省开封市夷山大街佳和世家1号楼14号铺1层 | J28: 11:30-14:30；17:30-21:00 | K28: 80-90元/人 | L28: unknown | M28: unknown | N28: unknown | O28: src_000097 | P28: pending_review | S28: 5 | T28: 携程附近列表显示店名、人均参考价及约11:30开门提示；精确地址和完整营业时间待核实。 携程附近美食页显示11:30营业，仅显示开门时间。 平台页面显示人均约82元/人，仅供消费预算参考，不是单道菜价格。 地址核查（2026-10-22）：Trip.com页面列出佳和世家1号楼14号铺1层及营业时段；平台资料仍需正式推荐前复核。 第三轮核查（2026-10-22）：Trip.com页面支持夷山大街佳和世家1号楼14号铺1层、11:30-14:30及17:30-21:00，页面可见2026-08-17用户点评；本轮未找到能可靠对应该分店的高德坐标。
A29: ven_000026 | C29: 梁山烤肉（东京总店） | D29: 梁山烤肉东京总店 | E29: 河南省开封市龙亭区万胜路（Trip.com当前餐厅详情写8号；另有用户游记及工商注册地址写1号，门牌未确认） | J29: 10:00-24:00 | K29: 60-70元/人 | L29: unknown | M29: unknown | N29: unknown | O29: src_000116 | P29: conflict | S29: 6 | T29: 携程附近列表显示店名、人均参考价及约10:00开门提示；精确地址、完整营业时间和菜单待核实。 携程附近美食页显示10:00营业，仅显示开门时间。 平台页面显示人均约65元/人，仅供消费预算参考，不是单道菜价格。 地址冲突（2026-10-22）：携程详情区写万胜路8号，但同页用户点评和BOSS企业信息列万胜路1号（辅助来源src_000099）。已标记conflict；须用高德地图或电话确认后才能作为正式导航地址。 二次核查（2026-10-22）：携程页面餐厅信息区写“万胜路8号”，同页用户点评写“万胜路1号”，BOSS企业信息也列“万胜路1号”。已将address改为地标级位置并明确门牌冲突；未联系商家确认前不得当作精确导航地址。 第三轮核查（2026-10-22）：Trip.com当前餐厅详情区仍列万胜路8号、10:00-24:00、电话18568673633，并有2026-04-25近期评价；但用户游记文字与BOSS工商注册地址写万胜路1号。餐厅详情区更适合作为候选导航线索，但未直接联系商家前仍保留conflict状态，不将1号或8号宣称为最终核实地址。
A30: ven_000027 | C30: 开封市福兴斋清真食品厂（福兴斋品牌） | D30: 福兴斋 | E30: 河南省开封市祥符区朱仙镇北关（食品加工厂址，非已确认的游客消费门店） | L30: unknown | M30: unknown | N30: unknown | O30: src_000101 | P30: pending_review | S30: 3 | T30: 商务部老字号数字博物馆支持品牌及桶子鸡产品信息，但该记录可能是生产主体而非游客可直接到店消费的门店；零售门店地址与营业信息待核实。 地址核查（2026-10-22）：祥符区政府食品生产监督公示列出该厂地址为朱仙镇北关。该记录是食品生产主体，不是已确认的游客可到店消费门店；正式推荐池应先核实其零售门店或替换为具体门店。 第三轮核查（2026-10-22）：该记录的政府公示来源支持食品生产主体厂址，但不能证明游客可直接在厂址消费或购买。建议从“游客餐饮推荐商家”候选池中排除，除非另行找到具体零售门店及其地址。
A31: ven_000028 | C31: 宜生斋 | D31: 宜生斋老庞家 | E31: 河南省开封市顺河回族区南羊小区1号楼1层西头 | L31: unknown | M31: unknown | N31: unknown | O31: src_000063 | P31: pending_review | S31: 2 | T31: 地址和桶子鸡/烧鸡主营产品来自商务部老字号数字博物馆；营业时间及当前门店状态待核实。 第三轮核查（2026-10-22）：商务部老字号数字博物馆页面明确写明宜生斋总店地址为顺河回族区南羊小区1号楼1层西头，并说明主营桶子鸡、烧鸡；地址有较强的品牌来源支持，但页面未提供高德坐标或当前营业状态，仍需地图/商家确认。
A32: ven_000029 | C32: 庞记桶子鸡（旗舰店） | D32: 庞记桶子鸡 | E32: 河南省开封市龙亭区黄河大街8号一层2号 | F32: 114.32264 | G32: 34.804717 | H32: GCJ-02 | I32: B0FFGZKNA5 | L32: unknown | M32: unknown | N32: unknown | O32: src_000087 | P32: pending_review | S32: 3 | T32: 高德开封美食榜将其列为桶子鸡候选商家，但本轮页面未提供可核实的精确地址、营业时间和门店详情。 地址/坐标核查（2026-10-22）：高德地点页提供黄河大街8号一层2号及坐标（GCJ-02）；页面存在较早用户评价，当前营业状态仍需确认。 第三轮核查（2026-10-22）：重新打开高德地点页确认黄河大街8号一层2号、坐标34.804717/114.322644及POI B0FFGZKNA5；页面电话18903785556，可见评价较早，当前营业状态需复核。
A33: ven_000030 | C33: 三胜街田庆辉田记米线 | D33: 田庆辉田记米线；田记米线 | E33: 河南省开封市龙亭区三胜前街7号 | F33: 114.35603 | G33: 34.800376 | H33: GCJ-02 | I33: B0FFG02SUH | L33: unknown | M33: unknown | N33: unknown | O33: src_000103 | P33: pending_review | S33: 4 | T33: 高德开封美食榜提供店名及米线介绍；精确地址、营业时间和实时菜单待核实。 地址核查未完成（2026-10-22）：高德2025美食榜只列店名/菜品；大众点评相册页（来源src_000102）可确认店名与菜品图片，但详情页触发美团验证，未能取得精确地址。抖音/美团/小红书公开可检索结果未找到可交叉确认的门牌，因此地址继续留空，不猜填。 二次核查（2026-10-22）：高德地点页补充精确地址“三胜前街7号”、坐标34.800376,114.356027（GCJ-02）和POI B0FFG02SUH；可见评价日期为2019-11-24，当前营业状态仍需复核。来源见src_000103。 第三轮核查（2026-10-22）：重新打开高德地点页确认三胜前街7号、坐标34.800376/114.356027、电话13569506620及POI B0FFG02SUH；可见用户评价仍为2019年，不能证明当前仍营业，保留待核实。
A34: ven_000031 | C34: 益品虾皇（鼎立总店） | D34: 益品虾皇鼎立总店 | I34: B0FFHXMMZP | L34: unknown | M34: unknown | N34: unknown | O34: src_000081 | P34: pending_review | S34: 4 | T34: 高德开封美食榜将其列为候选商家；精确地址、营业时间、价格及当前菜单待核实。 地址核查未完成（2026-10-22）：高德2025美食榜仅收录名称，未给出具体门牌；本轮公开检索未找到可交叉确认的高德POI或可靠的抖音/美团/小红书门店地址，地址继续留空，不按“鼎立总店”字样推测具体门牌。 二次核查（2026-10-22）：高德2025榜单中的“益品虾皇（鼎立总店）”链接对应POI标识B0FFHXMMZP，但详情页本轮无法成功打开，未获得地址/坐标。吉屋网另列同名商户“黄河路北段安泰警苑小区斜对面”（来源src_000104），尚不能确认与“鼎立总店”为同一分店，因此address仍留空，不猜填。 第三轮核查（2026-10-22）：高德2025美食榜仍出现“益品虾皇（鼎立总店）”，但其POI链接B0FFHXMMZP本轮返回404；公开检索未找到可确认该分店地址的美团/抖音/小红书页面。另一个网页提到黄河路北段安泰警苑附近的同名商户，但不能证明同一分店。地址继续留空，不猜填。
A35: ven_000032 | C35: 楼上楼灌汤包子馆（大梁路店） | D35: 楼上楼灌汤包子馆 | E35: 河南省开封市龙亭区大梁路与武夷路交叉口东南角（航天大酒店对面） | F35: 114.31881 | G35: 34.801561 | H35: GCJ-02 | I35: B0GRGOROMS | L35: unknown | M35: unknown | N35: unknown | O35: src_000082 | P35: candidate | S35: 2 | T35: 高德页面提供地址和坐标；推荐菜、营业时间及当前供应仍需核实。 第三轮核查（2026-10-22）：高德地点页支持大梁路与武夷路交叉口东南角、航天大酒店对面，坐标34.801561/114.318807及POI B0GRGOROMS；可见评价为2020年，当前营业状态需复核。

Sheet 17_vendor_foods
A1: 菜品供应关系 vendor_foods
A2: 仅收集候选与核实数据；不得把格式正确误判为事实真实。导入前请运行校验脚本。
